Workbook
Name BuiltIn_AutoFilter___3: #REF!

Sheet Informe
C1: FR-014 - V01
C2: INFORME DE PRUEBA DE SEGURIDAD ELÉCTRICA
E5: INFORME NÚMERO: | F5: =+Datos!A5 -> 0
B10: SOLICITANTE:
B13: DIRECCIÓN: | F13: =+Datos!C5 -> 0
B16: INFORMACIÓN DEL CONTACTO:
B20: EQUIPO:
B23: FABRICANTE:
B26: MODELO:
B29: NÚMERO DE SERIE:
B32: CÓDIGO INTERNO:
B35: FECHA RECEPCIÓN:
B38: FECHA DE MEDICIÓN:
B41: FECHA DE EMISIÓN:
B46: CONDICIONES AMBIENTALES
B48: Durante la medición, se midió la temperatura y humedad ambiental máximas y mínima. Los valores pomedios se reportan a continuación.
C50: TEMPERATURA | E50: =CONCATENATE(Datos!F12," °C") -> 21.5 °C
C51: HUMEDAD | E51: =CONCATENATE(Datos!F13," %hr") -> 52.75 %hr
B54: MÉTODO DE MEDICIÓN
B56: Para realizar esta prueba se siguen las especificaciones planteadas en la norma internacional ISO/IEC 60601-1.
B57: Según esta, los equipos se clasifican así:
B59: Según el tipo de protección contra descargas eléctricas
B60: A) Equipo alimentado internamente
B61: B) Equipo alimentado por una fuente externa de energía eléctrica.
B62: Equipo de clase I
B63: Incluye una medida de seguridad consistente en el conexionado del equipo conductor de protección a tierra, que forma parte del cableado fijo de la instalación, de forma que las partes accesibles no puedan hacerse activas en caso de fallo del aislamiento básico).
B64: Equipo de clase II
B65: Aislamiento doble o aislamiento reforzado, no existiendo provisión de puesta a tierra y confiando en las condiciones de la instalación.
B66: Según el grado de protección contra descargas eléctricas
B67: Equipo de Tipo B (protección contra descargas eléctricas, particularmente con la Corriente de fuga permisible, y la fiabilidad de la conexión a tierra si la hubiese).
... B74: PRUEBA DE LÍNEA
B76: Descripción: | C76: =+Datos!B17 -> Patrón conectado a linea y equipo a analizar conectado a Patrón. Equipo de prueba apagado.
B78: =+Datos!B18 -> Los valores de la tabla se expresan en V
B80: VALOR ESPERADO | D80: VALOR PROMEDIO MEDIDO PATRÓN | F80: APTO
B81: 220 ± 5% | D81: PL | F81: =+Datos!F21 -> NO
B84: =+Datos!B23:H23 -> PRUEBA DE RESISTENCIA EN PROTECCIÓN A TIERRA:
B86: Descripción: | C86: =+Datos!B24 -> Para todos los equipos biomédicos y según norma internacional IEC 60601-1, no debe superar los 0,2 Ω
B88: =+Datos!B25 -> Los valores de la tabla se expresan en Ω
B90: VALOR ESPERADO | D90: VALOR PROMEDIO MEDIDO PATRÓN | F90: APTO
B91: 0.2 | D91: PR | F91: =+Datos!G28 -> #DIV/0!
...

Sheet Datos
C1: FR-014 - V01
C2: INFORME DE PRUEBA DE SEGURIDAD ELÉCTRICA
A4: NÚMERO INFORME | B4: SOLICITANTE | C4: DIRECCIÓN | D4: NOMBRE CONTACTO | E4: TELÉFONO | F4: EQUIPO | G4: FABRICANTE | H4: MODELO | I4: SERIE | J4: CÓDIGO INTERNO | K4: FECHA DE RECEPCIÓN | L4: FECHA DE MEDICIÓN | M4: SITIO DE CALIBRACIÓN
B5: CARDIOPERFUSION | D5: CONRADO DELGADO | F5: TORRE ENDOSCOPIA + VIDEO GASTROSCOPIO TERAPEUTICO | G5: FUJI | H5: EP 6000 EG-760CT | I5: 2V696K311 7G411K149 | J5: 16794 | K5: 29-09-2022 | L5: 29-09-2022 | M5: CLINICA CENTENARIO PERUANO JAPONESA
A9: CONDICIONES AMBIENTALES
D11: MÍNIMA | E11: MÁXIMA | F11: PROMEDIO
C12: Temperatura (°C) | D12: 20.9 | E12: 22.1 | F12: =AVERAGE(D12:E12) -> 21.5
C13: Humedad (%hr) | D13: 51.3 | E13: 54.2 | F13: =AVERAGE(D13:E13) -> 52.75
A16: 1. | B16: PRUEBA DE LÍNEA
B17: Patrón conectado a linea y equipo a analizar conectado a Patrón. Equipo de prueba apagado. | K17: V
B18: =+CONCATENATE("Los valores de la tabla se expresan en ",K17) -> Los valores de la tabla se expresan en V
B20: VALOR | C20: FASE A NEUTRO | D20: NEUTRO A TIERRA | E20: FASE A TIERRA | F20: APTO
B21: 220 ± 5% | C21: LFN | D21: LNT | E21: LFT | F21: =IF(AND(C21 >= 209, C21 <= 231, D21 <= 5), "SI", "NO") -> NO
A23: 2. | B23: PRUEBA DE RESISTENCIA EN PROTECCIÓN A TIERRA:
B24: Para todos los equipos biomédicos y según norma internacional IEC 60601-1, no debe superar los 0,2 Ω
B25: =+CONCATENATE("Los valores de la tabla se expresan en ",K25) -> Los valores de la tabla se expresan en Ω | K25: Ω
B27: VALOR | C27: VALOR PATRÓN (1) | D27: VALOR PATRÓN (2) | E27: VALOR PATRÓN (3) | F27: PROMEDIO PATRÓN | G27: APTO
B28: 0.2 | C28: PR1 | D28: PR2 | E28: PR3 | F28: =AVERAGE(C28:E28) -> #DIV/0! | G28: =IF(F28<=B28,"SI","NO ") -> #DIV/0!
A31: 3.
B32: Determinar posibles fallas dependiendo de cada equipo
A33: 3.1 | B33: PRUEBA TIERRA
B34: =+CONCATENATE("Los valores de la tabla se expresan en ",K34) -> Los valores de la tabla se expresan en µA | K34: µA
B36: TIERRA | C36: EQUIPO BAJO PRUEBA | D36: FASE | E36: NEUTRO | F36: TIERRA | G36: MÁXIMO PERMITIDO | H36: VALOR PATRÓN 1 | I36: VALOR PATRÓN 2 | J36: VALOR PATRÓN 3 | K36: PROMEDIO PATRÓN | L36: APTO
C37: ON | D37: NORMAL | E37: CERRADO | F37: N.A. | G37: 500 | H37: TONC1 | I37: TONC2 | J37: TONC3 | K37: =AVERAGE(H37:J37) -> #DIV/0! | L37: =IF(K37<=G37,"SI","NO ") -> #DIV/0!
C38: OFF | D38: NORMAL | E38: ABIERTO | F38: N.A. | G38: 1000 | H38: TFNA1 | I38: TFNA2 | J38: TFNA3 | K38: =AVERAGE(H38:J38) -> #DIV/0! | L38: =IF(K38<=G38,"SI","NO ") -> #DIV/0!
C39: OFF | D39: OFF | E39: N.A. | F39: N.A. | G39: 500 | H39: TFF1 | I39: TFF2 | J39: TFF3 | K39: =AVERAGE(H39:J39) -> #DIV/0! | L39: =IF(K39<=G39,"SI","NO ") -> #DIV/0!
C40: OFF | D40: INVERTIDA | E40: ABIERTO | F40: N.A. | G40: 1000 | H40: TFIA1 | I40: TFIA2 | J40: TFIA3 | K40: =AVERAGE(H40:J40) -> #DIV/0! | L40: =IF(K40<=G40,"SI","NO ") -> #DIV/0!
C41: ON | D41: INVERTIDA | E41: CERRADO | F41: N.A. | G41: 500 | H41: TOIC1 | I41: TOIC2 | J41: TOIC3 | K41: =AVERAGE(H41:J41) -> #DIV/0! | L41: =IF(K41<=G41,"SI","NO ") -> #DIV/0!
A43: 3.2 | B43: PRUEBA CHASÍS | K43: µA
B44: =+CONCATENATE("Los valores de la tabla se expresan en ",K43) -> Los valores de la tabla se expresan en µA
B46: CHASIS | C46: EQUIPO BAJO PRUEBA | D46: FASE | E46: NEUTRO | F46: TIERRA | G46: MÁXIMO PERMITIDO | H46: VALOR PATRÓN 1 | I46: VALOR PATRÓN 2 | J46: VALOR PATRÓN 3 | K46: PROMEDIO PATRÓN | L46: APTO
C47: ON | D47: INVERTIDA | E47: CERRADO | F47: CERRADO | G47: 500 | H47: COICC1 | I47: COICC2 | J47: COICC3 | K47: =AVERAGE(H47:J47) -> #DIV/0! | L47: =IF(K47<=G47,"SI","NO ") -> #DIV/0!
C48: ON | D48: INVERTIDA | E48: CERRADO | F48: ABIERTO | G48: 500 | H48: COICA1 | I48: COICA2 | J48: COICA3 | K48: =AVERAGE(H48:J48) -> #DIV/0! | L48: =IF(K48<=G48,"SI","NO ") -> #DIV/0!
C49: OFF | D49: INVERTIDA | E49: ABIERTO | F49: ABIERTO | G49: 500 | H49: COIAA1 | I49: COIAA2 | J49: COIAA3 | K49: =AVERAGE(H49:J49) -> #DIV/0! | L49: =IF(K49<=G49,"SI","NO ") -> #DIV/0!
C50: OFF | D50: INVERTIDA | E50: ABIERTO | F50: CERRADO | G50: 500 | H50: COIAC1 | I50: COIAC2 | J50: COIAC3 | K50: =AVERAGE(H50:J50) -> #DIV/0! | L50: =IF(K50<=G50,"SI","NO ") -> #DIV/0!
C51: OFF | D51: OFF | E51: N.A. | F51: ABIERTO | G51: 500 | H51: COOA1 | I51: COOA2 | J51: COOA3 | K51: =AVERAGE(H51:J51) -> #DIV/0! | L51: =IF(K51<=G51,"SI","NO ") -> #DIV/0!
C52: OFF | D52: OFF | E52: N.A. | F52: CERRADO | G52: 500 | H52: COOC1 | I52: COOC2 | J52: COOC3 | K52: =AVERAGE(H52:J52) -> #DIV/0! | L52: =IF(K52<=G52,"SI","NO ") -> #DIV/0!
C53: OFF | D53: NORMAL | E53: ABIERTO | F53: CERRADO | G53: 500 | H53: CONAC1 | I53: CONAC2 | J53: CONAC3 | K53: =AVERAGE(H53:J53) -> #DIV/0! | L53: =IF(K53<=G53,"SI","NO ") -> #DIV/0!
C54: OFF | D54: NORMAL | E54: CERRADO | F54: CERRADO | G54: 500 | H54: CONCC1 | I54: CONCC2 | J54: CONCC3 | K54: =AVERAGE(H54:J54) -> #DIV/0! | L54: =IF(K54<=G54,"SI","NO ") -> #DIV/0!
C55: OFF | D55: NORMAL | E55: CERRADO | F55: ABIERTO | G55: 500 | H55: CONCA1 | I55: CONCA2 | J55: CONCA3 | K55: =AVERAGE(H55:J55) -> #DIV/0! | L55: =IF(K55<=G55,"SI","NO ") -> #DIV/0!
...

Sheet Patrones
B3: CÓDIGO | C3: DESCRIPCIÓN | D3: FECHA CAL | E3: CERTIFICADO DE CALIBRACIÓN | F3: PROVEEDOR
B4: PB-12 | C4: PB-12 Analizador de seguridad eléctrica Fluke ESA 615 | D4: J10804-21 | E4: 44306 | F4: SET&GAD
B5: PB-13 | C5: PB-13 Analizador de seguridad eléctrica Fluke ESA 615 | D5: J0908-21 | E5: 44411 | F5: SET&GAD
B6: PB-14 | C6: PB-14 Analizador de seguridad eléctrica Fluke ESA 615 | D6: J10904-21 | E6: 44306 | F6: SET&GAD
B7: PB-15 | C7: PB-15 Analizador de seguridad eléctrica Fluke ESA 615 | D7: J1008-21 | E7: 44411 | F7: SET&GAD

Sheet Clasificación
A1: Según el tipo de protección contra descargas eléctricas
A2: A) Equipo alimentado internamente
A3: B) Equipo alimentado por una fuente externa de energía eléctrica.
A4: Equipo de clase I
A5: Incluye una medida de seguridad consistente en el conexionado del equipo conductor de protección a tierra, que forma parte del cableado fijo de la instalación, de forma que las partes accesibles no puedan hacerse activas en caso de fallo del aislamiento básico).
A6: Equipo de clase II
A7: Aislamiento doble o aislamiento reforzado, no existiendo provisión de puesta a tierra y confiando en las condiciones de la instalación.
A8: Según el grado de protección contra descargas eléctricas
A9: Equipo de Tipo B (protección contra descargas eléctricas, particularmente con la
A10: Corriente de fuga permisible, y la fiabilidad de la conexión a tierra si la hubiese).
A11: Equipo de Tipo BF (equipo de tipo B, con parte aplicable de tipo F; flotante, parte
A12: Aplicable aislada de todas las otras partes del equipo).
... A14: Descargas eléctricas, que el equipo tipo BF, particularmente en relación con la corriente de fuga permisible, y dispone de una parte aplicable tipo F).

Sheet Versiones
C1: =+Informe!C1 -> FR-014 - V01
C2: =+Informe!C2 -> INFORME DE PRUEBA DE SEGURIDAD ELÉCTRICA
A4: Versión | B4: Descripción | E4: Responsables
A5: 1 | B5: Versión inicial. | E5: Elaboró: Daniela Gómez Alzate 2022-02-24 Aprobó: Sandra M. Pérez 2022-02-24

Sheet DV-IDENTITY-0
A1: =IF(Datos!1:1,"AAAAAF/d7gA=",0) -> 0 | B1: =AND(Datos!A1,"AAAAAF/d7gE=") -> #VALUE! | C1: =AND(Datos!B1,"AAAAAF/d7gI=") -> #VALUE! | D1: =AND(Datos!C1,"AAAAAF/d7gM=") -> #VALUE! | E1: =AND(Datos!D1,"AAAAAF/d7gQ=") -> #VALUE! | F1: =AND(Datos!E1,"AAAAAF/d7gU=") -> #VALUE! | G1: =AND(Datos!F1,"AAAAAF/d7gY=") -> #VALUE! | H1: =AND(Datos!G1,"AAAAAF/d7gc=") -> #VALUE! | I1: =AND(Datos!H1,"AAAAAF/d7gg=") -> #VALUE! | J1: =AND(Datos!I1,"AAAAAF/d7gk=") -> #VALUE! | K1: =AND(Datos!J1,"AAAAAF/d7go=") -> #VALUE! | L1: =AND(Datos!K1,"AAAAAF/d7gs=") -> #VALUE! | M1: =AND(Datos!L1,"AAAAAF/d7gw=") -> #VALUE! | N1: =AND(Datos!M1,"AAAAAF/d7g0=") -> #VALUE! | O1: =AND(Datos!N1,"AAAAAF/d7g4=") -> #VALUE! | P1: =AND(Datos!O1,"AAAAAF/d7g8=") -> #VALUE! | Q1: =AND(Datos!P1,"AAAAAF/d7hA=") -> #VALUE! | R1: =AND(Datos!Q1,"AAAAAF/d7hE=") -> #VALUE! | S1: =AND(Datos!R1,"AAAAAF/d7hI=") -> #VALUE! | T1: =AND(Datos!S1,"AAAAAF/d7hM=") -> #VALUE! | U1: =AND(Datos!T1,"AAAAAF/d7hQ=") -> #VALUE! | V1: =AND(Datos!U1,"AAAAAF/d7hU=") -> #VALUE! | W1: =AND(Datos!V1,"AAAAAF/d7hY=") -> #VALUE! | X1: =AND(Datos!W1,"AAAAAF/d7hc=") -> #VALUE! | Y1: =IF(Datos!#REF!,"AAAAAF/d7hg=",0) -> #REF! | Z1: =AND(Datos!#REF!,"AAAAAF/d7hk=") -> #REF! | AA1: =AND(Datos!#REF!,"AAAAAF/d7ho=") -> #REF! | AB1: =AND(Datos!#REF!,"AAAAAF/d7hs=") -> #REF! | AC1: =AND(Datos!#REF!,"AAAAAF/d7hw=") -> #REF! | AD1: =AND(Datos!#REF!,"AAAAAF/d7h0=") -> #REF! | AE1: =AND(Datos!#REF!,"AAAAAF/d7h4=") -> #REF! | AF1: =AND(Datos!#REF!,"AAAAAF/d7h8=") -> #REF! | AG1: =AND(Datos!#REF!,"AAAAAF/d7iA=") -> #REF! | AH1: =AND(Datos!#REF!,"AAAAAF/d7iE=") -> #REF! | AI1: =AND(Datos!#REF!,"AAAAAF/d7iI=") -> #REF! | AJ1: =AND(Datos!#REF!,"AAAAAF/d7iM=") -> #REF! | AK1: =AND(Datos!#REF!,"AAAAAF/d7iQ=") -> #REF! | AL1: =AND(Datos!#REF!,"AAAAAF/d7iU=") -> #REF! | AM1: =AND(Datos!#REF!,"AAAAAF/d7iY=") -> #REF! | AN1: =AND(Datos!#REF!,"AAAAAF/d7ic=") -> #REF! | AO1: =AND(Datos!#REF!,"AAAAAF/d7ig=") -> #REF! | AP1: =AND(Datos!#REF!,"AAAAAF/d7ik=") -> #REF! | AQ1: =AND(Datos!#REF!,"AAAAAF/d7io=") -> #REF! | AR1: =AND(Datos!#REF!,"AAAAAF/d7is=") -> #REF! | AS1: =AND(Datos!#REF!,"AAAAAF/d7iw=") -> #REF! | AT1: =AND(Datos!#REF!,"AAAAAF/d7i0=") -> #REF! | AU1: =AND(Datos!#REF!,"AAAAAF/d7i4=") -> #REF! | AV1: =AND(Datos!#REF!,"AAAAAF/d7i8=") -> #REF! | AW1: =IF(Datos!#REF!,"AAAAAF/d7jA=",0) -> #REF! | AX1: =AND(Datos!#REF!,"AAAAAF/d7jE=") -> #REF! | AY1: =AND(Datos!#REF!,"AAAAAF/d7jI=") -> #REF! | AZ1: =AND(Datos!#REF!,"AAAAAF/d7jM=") -> #REF! | BA1: =AND(Datos!#REF!,"AAAAAF/d7jQ=") -> #REF! | BB1: =AND(Datos!#REF!,"AAAAAF/d7jU=") -> #REF! | BC1: =AND(Datos!#REF!,"AAAAAF/d7jY=") -> #REF! | BD1: =AND(Datos!#REF!,"AAAAAF/d7jc=") -> #REF! | BE1: =AND(Datos!#REF!,"AAAAAF/d7jg=") -> #REF! | BF1: =AND(Datos!#REF!,"AAAAAF/d7jk=") -> #REF! | BG1: =AND(Datos!#REF!,"AAAAAF/d7jo=") -> #REF! | BH1: =AND(Datos!#REF!,"AAAAAF/d7js=") -> #REF! | BI1: =AND(Datos!#REF!,"AAAAAF/d7jw=") -> #REF! | BJ1: =AND(Datos!#REF!,"AAAAAF/d7j0=") -> #REF! | BK1: =AND(Datos!#REF!,"AAAAAF/d7j4=") -> #REF! | BL1: =AND(Datos!#REF!,"AAAAAF/d7j8=") -> #REF! | BM1: =AND(Datos!#REF!,"AAAAAF/d7kA=") -> #REF! | BN1: =AND(Datos!#REF!,"AAAAAF/d7kE=") -> #REF! | BO1: =AND(Datos!#REF!,"AAAAAF/d7kI=") -> #REF! | BP1: =AND(Datos!#REF!,"AAAAAF/d7kM=") -> #REF! | BQ1: =AND(Datos!#REF!,"AAAAAF/d7kQ=") -> #REF! | BR1: =AND(Datos!#REF!,"AAAAAF/d7kU=") -> #REF! | BS1: =AND(Datos!#REF!,"AAAAAF/d7kY=") -> #REF! | BT1: =AND(Datos!#REF!,"AAAAAF/d7kc=") -> #REF! | BU1: =IF(Datos!#REF!,"AAAAAF/d7kg=",0) -> #REF! | BV1: =AND(Datos!#REF!,"AAAAAF/d7kk=") -> #REF! | BW1: =AND(Datos!#REF!,"AAAAAF/d7ko=") -> #REF! | BX1: =AND(Datos!#REF!,"AAAAAF/d7ks=") -> #REF! | BY1: =AND(Datos!#REF!,"AAAAAF/d7kw=") -> #REF! | BZ1: =AND(Datos!#REF!,"AAAAAF/d7k0=") -> #REF! | CA1: =AND(Datos!#REF!,"AAAAAF/d7k4=") -> #REF! | CB1: =AND(Datos!#REF!,"AAAAAF/d7k8=") -> #REF! | CC1: =AND(Datos!#REF!,"AAAAAF/d7lA=") -> #REF! | CD1: =AND(Datos!#REF!,"AAAAAF/d7lE=") -> #REF! | CE1: =AND(Datos!#REF!,"AAAAAF/d7lI=") -> #REF! | CF1: =AND(Datos!#REF!,"AAAAAF/d7lM=") -> #REF! | CG1: =AND(Datos!#REF!,"AAAAAF/d7lQ=") -> #REF! | CH1: =AND(Datos!#REF!,"AAAAAF/d7lU=") -> #REF! | CI1: =AND(Datos!#REF!,"AAAAAF/d7lY=") -> #REF! | CJ1: =AND(Datos!#REF!,"AAAAAF/d7lc=") -> #REF! | CK1: =AND(Datos!#REF!,"AAAAAF/d7lg=") -> #REF! | CL1: =AND(Datos!#REF!,"AAAAAF/d7lk=") -> #REF! | CM1: =AND(Datos!#REF!,"AAAAAF/d7lo=") -> #REF! | CN1: =AND(Datos!#REF!,"AAAAAF/d7ls=") -> #REF! | CO1: =AND(Datos!#REF!,"AAAAAF/d7lw=") -> #REF! | CP1: =AND(Datos!#REF!,"AAAAAF/d7l0=") -> #REF! | CQ1: =AND(Datos!#REF!,"AAAAAF/d7l4=") -> #REF! | CR1: =AND(Datos!#REF!,"AAAAAF/d7l8=") -> #REF! | CS1: =IF(Datos!2:2,"AAAAAF/d7mA=",0) -> 0 | CT1: =AND(Datos!A2,"AAAAAF/d7mE=") -> #VALUE! | CU1: =AND(Datos!B2,"AAAAAF/d7mI=") -> #VALUE! | CV1: =AND(Datos!C2,"AAAAAF/d7mM=") -> #VALUE! | CW1: =AND(Datos!D2,"AAAAAF/d7mQ=") -> #VALUE! | CX1: =AND(Datos!E2,"AAAAAF/d7mU=") -> #VALUE! | CY1: =AND(Datos!F2,"AAAAAF/d7mY=") -> #VALUE! | CZ1: =AND(Datos!G2,"AAAAAF/d7mc=") -> #VALUE! | DA1: =AND(Datos!H2,"AAAAAF/d7mg=") -> #VALUE! | DB1: =AND(Datos!I2,"AAAAAF/d7mk=") -> #VALUE! | DC1: =AND(Datos!J2,"AAAAAF/d7mo=") -> #VALUE! | DD1: =AND(Datos!K2,"AAAAAF/d7ms=") -> #VALUE! | DE1: =AND(Datos!L2,"AAAAAF/d7mw=") -> #VALUE! | DF1: =AND(Datos!M2,"AAAAAF/d7m0=") -> #VALUE! | DG1: =AND(Datos!N2,"AAAAAF/d7m4=") -> #VALUE! | DH1: =AND(Datos!O2,"AAAAAF/d7m8=") -> #VALUE! | DI1: =AND(Datos!P2,"AAAAAF/d7nA=") -> #VALUE! | DJ1: =AND(Datos!Q2,"AAAAAF/d7nE=") -> #VALUE! | DK1: =AND(Datos!R2,"AAAAAF/d7nI=") -> #VALUE! | DL1: =AND(Datos!S2,"AAAAAF/d7nM=") -> #VALUE! | DM1: =AND(Datos!T2,"AAAAAF/d7nQ=") -> #VALUE! | DN1: =AND(Datos!U2,"AAAAAF/d7nU=") -> #VALUE! | DO1: =AND(Datos!V2,"AAAAAF/d7nY=") -> #VALUE! | DP1: =AND(Datos!W2,"AAAAAF/d7nc=") -> #VALUE! | DQ1: =IF(_xlfn.SINGLE(Datos!#REF!),"AAAAAF/d7ng=",0) -> #NAME? | DR1: =AND(Datos!#REF!,"AAAAAF/d7nk=") -> #REF! | DS1: =AND(Datos!#REF!,"AAAAAF/d7no=") -> #REF! | DT1: =AND(Datos!#REF!,"AAAAAF/d7ns=") -> #REF! | DU1: =AND(Datos!#REF!,"AAAAAF/d7nw=") -> #REF! | DV1: =AND(Datos!#REF!,"AAAAAF/d7n0=") -> #REF! | DW1: =AND(Datos!#REF!,"AAAAAF/d7n4=") -> #REF! | DX1: =AND(Datos!#REF!,"AAAAAF/d7n8=") -> #REF! | DY1: =AND(Datos!#REF!,"AAAAAF/d7oA=") -> #REF! | DZ1: =AND(Datos!#REF!,"AAAAAF/d7oE=") -> #REF! | EA1: =AND(Datos!#REF!,"AAAAAF/d7oI=") -> #REF! | EB1: =AND(Datos!#REF!,"AAAAAF/d7oM=") -> #REF! | EC1: =AND(Datos!#REF!,"AAAAAF/d7oQ=") -> #REF! | ED1: =AND(Datos!#REF!,"AAAAAF/d7oU=") -> #REF! | EE1: =AND(Datos!#REF!,"AAAAAF/d7oY=") -> #REF! | EF1: =AND(Datos!#REF!,"AAAAAF/d7oc=") -> #REF! | EG1: =AND(Datos!#REF!,"AAAAAF/d7og=") -> #REF! | EH1: =AND(Datos!#REF!,"AAAAAF/d7ok=") -> #REF! | EI1: =AND(Datos!#REF!,"AAAAAF/d7oo=") -> #REF! | EJ1: =AND(Datos!#REF!,"AAAAAF/d7os=") -> #REF! | EK1: =AND(Datos!#REF!,"AAAAAF/d7ow=") -> #REF! | EL1: =AND(Datos!#REF!,"AAAAAF/d7o0=") -> #REF! | EM1: =AND(Datos!#REF!,"AAAAAF/d7o4=") -> #REF! | EN1: =AND(Datos!#REF!,"AAAAAF/d7o8=") -> #REF! | EO1: =IF(Datos!3:3,"AAAAAF/d7pA=",0) -> 0 | EP1: =AND(Datos!A3,"AAAAAF/d7pE=") -> #VALUE! | EQ1: =AND(Datos!B3,"AAAAAF/d7pI=") -> #VALUE! | ER1: =AND(Datos!C3,"AAAAAF/d7pM=") -> #VALUE! | ES1: =AND(Datos!D3,"AAAAAF/d7pQ=") -> #VALUE! | ET1: =AND(Datos!E3,"AAAAAF/d7pU=") -> #VALUE! | EU1: =AND(Datos!F3,"AAAAAF/d7pY=") -> #VALUE! | EV1: =AND(Datos!G3,"AAAAAF/d7pc=") -> #VALUE! | EW1: =AND(Datos!H3,"AAAAAF/d7pg=") -> #VALUE! | EX1: =AND(Datos!I3,"AAAAAF/d7pk=") -> #VALUE! | EY1: =AND(Datos!J3,"AAAAAF/d7po=") -> #VALUE! | EZ1: =AND(Datos!K3,"AAAAAF/d7ps=") -> #VALUE! | FA1: =AND(Datos!L3,"AAAAAF/d7pw=") -> #VALUE! | FB1: =AND(Datos!M3,"AAAAAF/d7p0=") -> #VALUE! | FC1: =AND(Datos!N3,"AAAAAF/d7p4=") -> #VALUE! | FD1: =AND(Datos!O3,"AAAAAF/d7p8=") -> #VALUE! | FE1: =AND(Datos!P3,"AAAAAF/d7qA=") -> #VALUE! | FF1: =AND(Datos!Q3,"AAAAAF/d7qE=") -> #VALUE! | FG1: =AND(Datos!R3,"AAAAAF/d7qI=") -> #VALUE! | FH1: =AND(Datos!S3,"AAAAAF/d7qM=") -> #VALUE! | FI1: =AND(Datos!T3,"AAAAAF/d7qQ=") -> #VALUE! | FJ1: =AND(Datos!U3,"AAAAAF/d7qU=") -> #VALUE! | FK1: =AND(Datos!V3,"AAAAAF/d7qY=") -> #VALUE! | FL1: =AND(Datos!W3,"AAAAAF/d7qc=") -> #VALUE! | FM1: =IF(Datos!4:4,"AAAAAF/d7qg=",0) -> 0 | FN1: =AND(Datos!A4,"AAAAAF/d7qk=") -> #VALUE! | FO1: =AND(Datos!B4,"AAAAAF/d7qo=") -> #VALUE! | FP1: =AND(Datos!C4,"AAAAAF/d7qs=") -> #VALUE! | FQ1: =AND(Datos!D4,"AAAAAF/d7qw=") -> #VALUE! | FR1: =AND(Datos!E4,"AAAAAF/d7q0=") -> #VALUE! | FS1: =AND(Datos!F4,"AAAAAF/d7q4=") -> #VALUE! | FT1: =AND(Datos!G4,"AAAAAF/d7q8=") -> #VALUE! | FU1: =AND(Datos!H4,"AAAAAF/d7rA=") -> #VALUE! | FV1: =AND(Datos!I4,"AAAAAF/d7rE=") -> #VALUE! | FW1: =AND(Datos!J4,"AAAAAF/d7rI=") -> #VALUE! | FX1: =AND(Datos!K4,"AAAAAF/d7rM=") -> #VALUE! | FY1: =AND(Datos!L4,"AAAAAF/d7rQ=") -> #VALUE! | FZ1: =AND(Datos!M4,"AAAAAF/d7rU=") -> #VALUE! | GA1: =AND(Datos!N4,"AAAAAF/d7rY=") -> #VALUE! | GB1: =AND(Datos!O4,"AAAAAF/d7rc=") -> #VALUE! | GC1: =AND(Datos!P4,"AAAAAF/d7rg=") -> #VALUE! | GD1: =AND(Datos!Q4,"AAAAAF/d7rk=") -> #VALUE! | GE1: =AND(Datos!R4,"AAAAAF/d7ro=") -> #VALUE! | GF1: =AND(Datos!S4,"AAAAAF/d7rs=") -> #VALUE! | GG1: =AND(Datos!T4,"AAAAAF/d7rw=") -> #VALUE! | GH1: =AND(Datos!U4,"AAAAAF/d7r0=") -> #VALUE! | GI1: =AND(Datos!V4,"AAAAAF/d7r4=") -> #VALUE! | GJ1: =AND(Datos!W4,"AAAAAF/d7r8=") -> #VALUE! | GK1: =IF(Datos!5:5,"AAAAAF/d7sA=",0) -> 0 | GL1: =AND(Datos!A5,"AAAAAF/d7sE=") -> #VALUE! | GM1: =AND(Datos!B5,"AAAAAF/d7sI=") -> #VALUE! | GN1: =AND(Datos!C5,"AAAAAF/d7sM=") -> #VALUE! | GO1: =AND(Datos!D5,"AAAAAF/d7sQ=") -> #VALUE! | GP1: =AND(Datos!E5,"AAAAAF/d7sU=") -> #VALUE! | GQ1: =AND(Datos!F5,"AAAAAF/d7sY=") -> #VALUE! | GR1: =AND(Datos!G5,"AAAAAF/d7sc=") -> #VALUE! | GS1: =AND(Datos!H5,"AAAAAF/d7sg=") -> #VALUE! | GT1: =AND(Datos!I5,"AAAAAF/d7sk=") -> #VALUE! | GU1: =AND(Datos!J5,"AAAAAF/d7so=") -> #VALUE! | GV1: =AND(Datos!K5,"AAAAAF/d7ss=") -> #VALUE! | GW1: =AND(Datos!L5,"AAAAAF/d7sw=") -> #VALUE! | GX1: =AND(Datos!M5,"AAAAAF/d7s0=") -> #VALUE! | GY1: =AND(Datos!N5,"AAAAAF/d7s4=") -> #VALUE! | GZ1: =AND(Datos!O5,"AAAAAF/d7s8=") -> #VALUE! | HA1: =AND(Datos!P5,"AAAAAF/d7tA=") -> #VALUE! | HB1: =AND(Datos!Q5,"AAAAAF/d7tE=") -> #VALUE! | HC1: =AND(Datos!R5,"AAAAAF/d7tI=") -> #VALUE! | HD1: =AND(Datos!S5,"AAAAAF/d7tM=") -> #VALUE! | HE1: =AND(Datos!T5,"AAAAAF/d7tQ=") -> #VALUE! | HF1: =AND(Datos!U5,"AAAAAF/d7tU=") -> #VALUE! | HG1: =AND(Datos!V5,"AAAAAF/d7tY=") -> #VALUE! | HH1: =AND(Datos!W5,"AAAAAF/d7tc=") -> #VALUE! | HI1: =IF(Datos!6:6,"AAAAAF/d7tg=",0) -> 0 | HJ1: =AND(Datos!A6,"AAAAAF/d7tk=") -> #VALUE! | HK1: =AND(Datos!B6,"AAAAAF/d7to=") -> #VALUE! | HL1: =AND(Datos!C6,"AAAAAF/d7ts=") -> #VALUE! | HM1: =AND(Datos!D6,"AAAAAF/d7tw=") -> #VALUE! | HN1: =AND(Datos!E6,"AAAAAF/d7t0=") -> #VALUE! | HO1: =AND(Datos!F6,"AAAAAF/d7t4=") -> #VALUE! | HP1: =AND(Datos!G6,"AAAAAF/d7t8=") -> #VALUE! | HQ1: =AND(Datos!H6,"AAAAAF/d7uA=") -> #VALUE! | HR1: =AND(Datos!I6,"AAAAAF/d7uE=") -> #VALUE! | HS1: =AND(Datos!J6,"AAAAAF/d7uI=") -> #VALUE! | HT1: =AND(Datos!K6,"AAAAAF/d7uM=") -> #VALUE! | HU1: =AND(Datos!L6,"AAAAAF/d7uQ=") -> #VALUE! | HV1: =AND(Datos!M6,"AAAAAF/d7uU=") -> #VALUE! | HW1: =AND(Datos!N6,"AAAAAF/d7uY=") -> #VALUE! | HX1: =AND(Datos!O6,"AAAAAF/d7uc=") -> #VALUE! | HY1: =AND(Datos!P6,"AAAAAF/d7ug=") -> #VALUE! | HZ1: =AND(Datos!Q6,"AAAAAF/d7uk=") -> #VALUE! | IA1: =AND(Datos!R6,"AAAAAF/d7uo=") -> #VALUE! | IB1: =AND(Datos!S6,"AAAAAF/d7us=") -> #VALUE! | IC1: =AND(Datos!T6,"AAAAAF/d7uw=") -> #VALUE! | ID1: =AND(Datos!U6,"AAAAAF/d7u0=") -> #VALUE! | IE1: =AND(Datos!V6,"AAAAAF/d7u4=") -> #VALUE! | IF1: =AND(Datos!W6,"AAAAAF/d7u8=") -> #VALUE! | IG1: =IF(Datos!7:7,"AAAAAF/d7vA=",0) -> 0 | IH1: =AND(Datos!A7,"AAAAAF/d7vE=") -> #VALUE! | II1: =AND(Datos!B7,"AAAAAF/d7vI=") -> #VALUE! | IJ1: =AND(Datos!C7,"AAAAAF/d7vM=") -> #VALUE! | IK1: =AND(Datos!D7,"AAAAAF/d7vQ=") -> #VALUE! | IL1: =AND(Datos!E7,"AAAAAF/d7vU=") -> #VALUE! | IM1: =AND(Datos!F7,"AAAAAF/d7vY=") -> #VALUE! | IN1: =AND(Datos!G7,"AAAAAF/d7vc=") -> #VALUE! | IO1: =AND(Datos!H7,"AAAAAF/d7vg=") -> #VALUE! | IP1: =AND(Datos!I7,"AAAAAF/d7vk=") -> #VALUE! | IQ1: =AND(Datos!J7,"AAAAAF/d7vo=") -> #VALUE! | IR1: =AND(Datos!K7,"AAAAAF/d7vs=") -> #VALUE! | IS1: =AND(Datos!L7,"AAAAAF/d7vw=") -> #VALUE! | IT1: =AND(Datos!M7,"AAAAAF/d7v0=") -> #VALUE! | IU1: =AND(Datos!N7,"AAAAAF/d7v4=") -> #VALUE! | IV1: =AND(Datos!O7,"AAAAAF/d7v8=") -> #VALUE!
A2: =AND(Datos!P7,"AAAAAGfv/wA=") -> #VALUE! | B2: =AND(Datos!Q7,"AAAAAGfv/wE=") -> #VALUE! | C2: =AND(Datos!R7,"AAAAAGfv/wI=") -> #VALUE! | D2: =AND(Datos!S7,"AAAAAGfv/wM=") -> #VALUE! | E2: =AND(Datos!T7,"AAAAAGfv/wQ=") -> #VALUE! | F2: =AND(Datos!U7,"AAAAAGfv/wU=") -> #VALUE! | G2: =AND(Datos!V7,"AAAAAGfv/wY=") -> #VALUE! | H2: =AND(Datos!W7,"AAAAAGfv/wc=") -> #VALUE! | I2: =IF(Datos!#REF!,"AAAAAGfv/wg=",0) -> #REF! | J2: =AND(Datos!#REF!,"AAAAAGfv/wk=") -> #REF! | K2: =AND(Datos!#REF!,"AAAAAGfv/wo=") -> #REF! | L2: =AND(Datos!#REF!,"AAAAAGfv/ws=") -> #REF! | M2: =AND(Datos!#REF!,"AAAAAGfv/ww=") -> #REF! | N2: =AND(Datos!#REF!,"AAAAAGfv/w0=") -> #REF! | O2: =AND(Datos!#REF!,"AAAAAGfv/w4=") -> #REF! | P2: =AND(Datos!#REF!,"AAAAAGfv/w8=") -> #REF! | Q2: =AND(Datos!#REF!,"AAAAAGfv/xA=") -> #REF! | R2: =AND(Datos!#REF!,"AAAAAGfv/xE=") -> #REF! | S2: =AND(Datos!#REF!,"AAAAAGfv/xI=") -> #REF! | T2: =AND(Datos!#REF!,"AAAAAGfv/xM=") -> #REF! | U2: =AND(Datos!#REF!,"AAAAAGfv/xQ=") -> #REF! | V2: =AND(Datos!#REF!,"AAAAAGfv/xU=") -> #REF! | W2: =AND(Datos!#REF!,"AAAAAGfv/xY=") -> #REF! | X2: =AND(Datos!#REF!,"AAAAAGfv/xc=") -> #REF! | Y2: =AND(Datos!#REF!,"AAAAAGfv/xg=") -> #REF! | Z2: =AND(Datos!#REF!,"AAAAAGfv/xk=") -> #REF! | AA2: =AND(Datos!#REF!,"AAAAAGfv/xo=") -> #REF! | AB2: =AND(Datos!#REF!,"AAAAAGfv/xs=") -> #REF! | AC2: =AND(Datos!#REF!,"AAAAAGfv/xw=") -> #REF! | AD2: =AND(Datos!#REF!,"AAAAAGfv/x0=") -> #REF! | AE2: =AND(Datos!#REF!,"AAAAAGfv/x4=") -> #REF! | AF2: =AND(Datos!#REF!,"AAAAAGfv/x8=") -> #REF! | AG2: =IF(Datos!13:13,"AAAAAGfv/yA=",0) -> 0 | AH2: =AND(Datos!A13,"AAAAAGfv/yE=") -> #VALUE! | AI2: =AND(Datos!B13,"AAAAAGfv/yI=") -> #VALUE! | AJ2: =AND(Datos!C13,"AAAAAGfv/yM=") -> #VALUE! | AK2: =AND(Datos!D13,"AAAAAGfv/yQ=") -> #VALUE! | AL2: =AND(Datos!E13,"AAAAAGfv/yU=") -> #VALUE! | AM2: =AND(Datos!F13,"AAAAAGfv/yY=") -> #VALUE! | AN2: =AND(Datos!G13,"AAAAAGfv/yc=") -> #VALUE! | AO2: =AND(Datos!H13,"AAAAAGfv/yg=") -> #VALUE! | AP2: =AND(Datos!I13,"AAAAAGfv/yk=") -> #VALUE! | AQ2: =AND(Datos!J13,"AAAAAGfv/yo=") -> #VALUE! | AR2: =AND(Datos!K13,"AAAAAGfv/ys=") -> #VALUE! | AS2: =AND(Datos!L13,"AAAAAGfv/yw=") -> #VALUE! | AT2: =AND(Datos!M13,"AAAAAGfv/y0=") -> #VALUE! | AU2: =AND(Datos!N13,"AAAAAGfv/y4=") -> #VALUE! | AV2: =AND(Datos!O13,"AAAAAGfv/y8=") -> #VALUE! | AW2: =AND(Datos!P13,"AAAAAGfv/zA=") -> #VALUE! | AX2: =AND(Datos!Q13,"AAAAAGfv/zE=") -> #VALUE! | AY2: =AND(Datos!R13,"AAAAAGfv/zI=") -> #VALUE! | AZ2: =AND(Datos!S13,"AAAAAGfv/zM=") -> #VALUE! | BA2: =AND(Datos!T13,"AAAAAGfv/zQ=") -> #VALUE! | BB2: =AND(Datos!U13,"AAAAAGfv/zU=") -> #VALUE! | BC2: =AND(Datos!V13,"AAAAAGfv/zY=") -> #VALUE! | BD2: =AND(Datos!W13,"AAAAAGfv/zc=") -> #VALUE! | BE2: =IF(Datos!16:16,"AAAAAGfv/zg=",0) -> 0 | BF2: =AND(Datos!A16,"AAAAAGfv/zk=") -> #VALUE! | BG2: =AND(Datos!B16,"AAAAAGfv/zo=") -> #VALUE! | BH2: =AND(Datos!C16,"AAAAAGfv/zs=") -> #VALUE! | BI2: =AND(Datos!D16,"AAAAAGfv/zw=") -> #VALUE! | BJ2: =AND(Datos!E16,"AAAAAGfv/z0=") -> #VALUE! | BK2: =AND(Datos!F16,"AAAAAGfv/z4=") -> #VALUE! | BL2: =AND(Datos!G16,"AAAAAGfv/z8=") -> #VALUE! | BM2: =AND(Datos!H16,"AAAAAGfv/0A=") -> #VALUE! | BN2: =AND(Datos!I16,"AAAAAGfv/0E=") -> #VALUE! | BO2: =AND(Datos!J16,"AAAAAGfv/0I=") -> #VALUE! | BP2: =AND(Datos!K16,"AAAAAGfv/0M=") -> #VALUE! | BQ2: =AND(Datos!L16,"AAAAAGfv/0Q=") -> #VALUE! | BR2: =AND(Datos!M16,"AAAAAGfv/0U=") -> #VALUE! | BS2: =AND(Datos!N16,"AAAAAGfv/0Y=") -> #VALUE! | BT2: =AND(Datos!O16,"AAAAAGfv/0c=") -> #VALUE! | BU2: =AND(Datos!P16,"AAAAAGfv/0g=") -> #VALUE! | BV2: =AND(Datos!Q16,"AAAAAGfv/0k=") -> #VALUE! | BW2: =AND(Datos!R16,"AAAAAGfv/0o=") -> #VALUE! | BX2: =AND(Datos!S16,"AAAAAGfv/0s=") -> #VALUE! | BY2: =AND(Datos!T16,"AAAAAGfv/0w=") -> #VALUE! | BZ2: =AND(Datos!U16,"AAAAAGfv/00=") -> #VALUE! | CA2: =AND(Datos!V16,"AAAAAGfv/04=") -> #VALUE! | CB2: =AND(Datos!W16,"AAAAAGfv/08=") -> #VALUE! | CC2: =IF(Datos!17:17,"AAAAAGfv/1A=",0) -> 0 | CD2: =AND(Datos!A17,"AAAAAGfv/1E=") -> #VALUE! | CE2: =AND(Datos!B17,"AAAAAGfv/1I=") -> #VALUE! | CF2: =AND(Datos!C17,"AAAAAGfv/1M=") -> #VALUE! | CG2: =AND(Datos!D17,"AAAAAGfv/1Q=") -> #VALUE! | CH2: =AND(Datos!E17,"AAAAAGfv/1U=") -> #VALUE! | CI2: =AND(Datos!F17,"AAAAAGfv/1Y=") -> #VALUE! | CJ2: =AND(Datos!G17,"AAAAAGfv/1c=") -> #VALUE! | CK2: =AND(Datos!H17,"AAAAAGfv/1g=") -> #VALUE! | CL2: =AND(Datos!I17,"AAAAAGfv/1k=") -> #VALUE! | CM2: =AND(Datos!J17,"AAAAAGfv/1o=") -> #VALUE! | CN2: =AND(Datos!K17,"AAAAAGfv/1s=") -> #VALUE! | CO2: =AND(Datos!L17,"AAAAAGfv/1w=") -> #VALUE! | CP2: =AND(Datos!M17,"AAAAAGfv/10=") -> #VALUE! | CQ2: =AND(Datos!N17,"AAAAAGfv/14=") -> #VALUE! | CR2: =AND(Datos!O17,"AAAAAGfv/18=") -> #VALUE! | CS2: =AND(Datos!P17,"AAAAAGfv/2A=") -> #VALUE! | CT2: =AND(Datos!Q17,"AAAAAGfv/2E=") -> #VALUE! | CU2: =AND(Datos!R17,"AAAAAGfv/2I=") -> #VALUE! | CV2: =AND(Datos!S17,"AAAAAGfv/2M=") -> #VALUE! | CW2: =AND(Datos!T17,"AAAAAGfv/2Q=") -> #VALUE! | CX2: =AND(Datos!U17,"AAAAAGfv/2U=") -> #VALUE! | CY2: =AND(Datos!V17,"AAAAAGfv/2Y=") -> #VALUE! | CZ2: =AND(Datos!W17,"AAAAAGfv/2c=") -> #VALUE! | DA2: =IF(Datos!18:18,"AAAAAGfv/2g=",0) -> 0 | DB2: =AND(Datos!A18,"AAAAAGfv/2k=") -> #VALUE! | DC2: =AND(Datos!B18,"AAAAAGfv/2o=") -> #VALUE! | DD2: =AND(Datos!C18,"AAAAAGfv/2s=") -> #VALUE! | DE2: =AND(Datos!D18,"AAAAAGfv/2w=") -> #VALUE! | DF2: =AND(Datos!E18,"AAAAAGfv/20=") -> #VALUE! | DG2: =AND(Datos!F18,"AAAAAGfv/24=") -> #VALUE! | DH2: =AND(Datos!G18,"AAAAAGfv/28=") -> #VALUE! | DI2: =AND(Datos!H18,"AAAAAGfv/3A=") -> #VALUE! | DJ2: =AND(Datos!I18,"AAAAAGfv/3E=") -> #VALUE! | DK2: =AND(Datos!J18,"AAAAAGfv/3I=") -> #VALUE! | DL2: =AND(Datos!K18,"AAAAAGfv/3M=") -> #VALUE! | DM2: =AND(Datos!L18,"AAAAAGfv/3Q=") -> #VALUE! | DN2: =AND(Datos!M18,"AAAAAGfv/3U=") -> #VALUE! | DO2: =AND(Datos!N18,"AAAAAGfv/3Y=") -> #VALUE! | DP2: =AND(Datos!O18,"AAAAAGfv/3c=") -> #VALUE! | DQ2: =AND(Datos!P18,"AAAAAGfv/3g=") -> #VALUE! | DR2: =AND(Datos!Q18,"AAAAAGfv/3k=") -> #VALUE! | DS2: =AND(Datos!R18,"AAAAAGfv/3o=") -> #VALUE! | DT2: =AND(Datos!S18,"AAAAAGfv/3s=") -> #VALUE! | DU2: =AND(Datos!T18,"AAAAAGfv/3w=") -> #VALUE! | DV2: =AND(Datos!U18,"AAAAAGfv/30=") -> #VALUE! | DW2: =AND(Datos!V18,"AAAAAGfv/34=") -> #VALUE! | DX2: =AND(Datos!W18,"AAAAAGfv/38=") -> #VALUE! | DY2: =IF(Datos!19:19,"AAAAAGfv/4A=",0) -> 0 | DZ2: =AND(Datos!A19,"AAAAAGfv/4E=") -> #VALUE! | EA2: =AND(Datos!B19,"AAAAAGfv/4I=") -> #VALUE! | EB2: =AND(Datos!C19,"AAAAAGfv/4M=") -> #VALUE! | EC2: =AND(Datos!D19,"AAAAAGfv/4Q=") -> #VALUE! | ED2: =AND(Datos!E19,"AAAAAGfv/4U=") -> #VALUE! | EE2: =AND(Datos!F19,"AAAAAGfv/4Y=") -> #VALUE! | EF2: =AND(Datos!G19,"AAAAAGfv/4c=") -> #VALUE! | EG2: =AND(Datos!H19,"AAAAAGfv/4g=") -> #VALUE! | EH2: =AND(Datos!I19,"AAAAAGfv/4k=") -> #VALUE! | EI2: =AND(Datos!J19,"AAAAAGfv/4o=") -> #VALUE! | EJ2: =AND(Datos!K19,"AAAAAGfv/4s=") -> #VALUE! | EK2: =AND(Datos!L19,"AAAAAGfv/4w=") -> #VALUE! | EL2: =AND(Datos!M19,"AAAAAGfv/40=") -> #VALUE! | EM2: =AND(Datos!N19,"AAAAAGfv/44=") -> #VALUE! | EN2: =AND(Datos!O19,"AAAAAGfv/48=") -> #VALUE! | EO2: =AND(Datos!P19,"AAAAAGfv/5A=") -> #VALUE! | EP2: =AND(Datos!Q19,"AAAAAGfv/5E=") -> #VALUE! | EQ2: =AND(Datos!R19,"AAAAAGfv/5I=") -> #VALUE! | ER2: =AND(Datos!S19,"AAAAAGfv/5M=") -> #VALUE! | ES2: =AND(Datos!T19,"AAAAAGfv/5Q=") -> #VALUE! | ET2: =AND(Datos!U19,"AAAAAGfv/5U=") -> #VALUE! | EU2: =AND(Datos!V19,"AAAAAGfv/5Y=") -> #VALUE! | EV2: =AND(Datos!W19,"AAAAAGfv/5c=") -> #VALUE! | EW2: =IF(Datos!20:20,"AAAAAGfv/5g=",0) -> 0 | EX2: =AND(Datos!A20,"AAAAAGfv/5k=") -> #VALUE! | EY2: =AND(Datos!B20,"AAAAAGfv/5o=") -> #VALUE! | EZ2: =AND(Datos!C20,"AAAAAGfv/5s=") -> #VALUE! | FA2: =AND(Datos!D20,"AAAAAGfv/5w=") -> #VALUE! | FB2: =AND(Datos!E20,"AAAAAGfv/50=") -> #VALUE! | FC2: =AND(Datos!#REF!,"AAAAAGfv/54=") -> #REF! | FD2: =AND(Datos!#REF!,"AAAAAGfv/58=") -> #REF! | FE2: =AND(Datos!F20,"AAAAAGfv/6A=") -> #VALUE! | FF2: =AND(Datos!I20,"AAAAAGfv/6E=") -> #VALUE! | FG2: =AND(Datos!J20,"AAAAAGfv/6I=") -> #VALUE! | FH2: =AND(Datos!K20,"AAAAAGfv/6M=") -> #VALUE! | FI2: =AND(Datos!L20,"AAAAAGfv/6Q=") -> #VALUE! | FJ2: =AND(Datos!M20,"AAAAAGfv/6U=") -> #VALUE! | FK2: =AND(Datos!N20,"AAAAAGfv/6Y=") -> #VALUE! | FL2: =AND(Datos!O20,"AAAAAGfv/6c=") -> #VALUE! | FM2: =AND(Datos!P20,"AAAAAGfv/6g=") -> #VALUE! | FN2: =AND(Datos!Q20,"AAAAAGfv/6k=") -> #VALUE! | FO2: =AND(Datos!R20,"AAAAAGfv/6o=") -> #VALUE! | FP2: =AND(Datos!S20,"AAAAAGfv/6s=") -> #VALUE! | FQ2: =AND(Datos!T20,"AAAAAGfv/6w=") -> #VALUE! | FR2: =AND(Datos!U20,"AAAAAGfv/60=") -> #VALUE! | FS2: =AND(Datos!V20,"AAAAAGfv/64=") -> #VALUE! | FT2: =AND(Datos!W20,"AAAAAGfv/68=") -> #VALUE! | FU2: =IF(Datos!21:21,"AAAAAGfv/7A=",0) -> 0 | FV2: =AND(Datos!A21,"AAAAAGfv/7E=") -> #VALUE! | FW2: =AND(Datos!B21,"AAAAAGfv/7I=") -> #VALUE! | FX2: =AND(Datos!C21,"AAAAAGfv/7M=") -> #VALUE! | FY2: =AND(Datos!D21,"AAAAAGfv/7Q=") -> #VALUE! | FZ2: =AND(Datos!E21,"AAAAAGfv/7U=") -> #VALUE! | GA2: =AND(Datos!#REF!,"AAAAAGfv/7Y=") -> #REF! | GB2: =AND(Datos!#REF!,"AAAAAGfv/7c=") -> #REF! | GC2: =AND(Datos!F21,"AAAAAGfv/7g=") -> #VALUE! | GD2: =AND(Datos!I21,"AAAAAGfv/7k=") -> #VALUE! | GE2: =AND(Datos!J21,"AAAAAGfv/7o=") -> #VALUE! | GF2: =AND(Datos!K21,"AAAAAGfv/7s=") -> #VALUE! | GG2: =AND(Datos!L21,"AAAAAGfv/7w=") -> #VALUE! | GH2: =AND(Datos!M21,"AAAAAGfv/70=") -> #VALUE! | GI2: =AND(Datos!N21,"AAAAAGfv/74=") -> #VALUE! | GJ2: =AND(Datos!O21,"AAAAAGfv/78=") -> #VALUE! | GK2: =AND(Datos!P21,"AAAAAGfv/8A=") -> #VALUE! | GL2: =AND(Datos!Q21,"AAAAAGfv/8E=") -> #VALUE! | GM2: =AND(Datos!R21,"AAAAAGfv/8I=") -> #VALUE! | GN2: =AND(Datos!S21,"AAAAAGfv/8M=") -> #VALUE! | GO2: =AND(Datos!T21,"AAAAAGfv/8Q=") -> #VALUE! | GP2: =AND(Datos!U21,"AAAAAGfv/8U=") -> #VALUE! | GQ2: =AND(Datos!V21,"AAAAAGfv/8Y=") -> #VALUE! | GR2: =AND(Datos!W21,"AAAAAGfv/8c=") -> #VALUE! | GS2: =IF(Datos!22:22,"AAAAAGfv/8g=",0) -> 0 | GT2: =AND(Datos!A22,"AAAAAGfv/8k=") -> #VALUE! | GU2: =AND(Datos!B22,"AAAAAGfv/8o=") -> #VALUE! | GV2: =AND(Datos!C22,"AAAAAGfv/8s=") -> #VALUE! | GW2: =AND(Datos!D22,"AAAAAGfv/8w=") -> #VALUE! | GX2: =AND(Datos!E22,"AAAAAGfv/80=") -> #VALUE! | GY2: =AND(Datos!F22,"AAAAAGfv/84=") -> #VALUE! | GZ2: =AND(Datos!G22,"AAAAAGfv/88=") -> #VALUE! | HA2: =AND(Datos!H22,"AAAAAGfv/9A=") -> #VALUE! | HB2: =AND(Datos!I22,"AAAAAGfv/9E=") -> #VALUE! | HC2: =AND(Datos!J22,"AAAAAGfv/9I=") -> #VALUE! | HD2: =AND(Datos!K22,"AAAAAGfv/9M=") -> #VALUE! | HE2: =AND(Datos!L22,"AAAAAGfv/9Q=") -> #VALUE! | HF2: =AND(Datos!M22,"AAAAAGfv/9U=") -> #VALUE! | HG2: =AND(Datos!N22,"AAAAAGfv/9Y=") -> #VALUE! | HH2: =AND(Datos!O22,"AAAAAGfv/9c=") -> #VALUE! | HI2: =AND(Datos!P22,"AAAAAGfv/9g=") -> #VALUE! | HJ2: =AND(Datos!Q22,"AAAAAGfv/9k=") -> #VALUE! | HK2: =AND(Datos!R22,"AAAAAGfv/9o=") -> #VALUE! | HL2: =AND(Datos!S22,"AAAAAGfv/9s=") -> #VALUE! | HM2: =AND(Datos!T22,"AAAAAGfv/9w=") -> #VALUE! | HN2: =AND(Datos!U22,"AAAAAGfv/90=") -> #VALUE! | HO2: =AND(Datos!V22,"AAAAAGfv/94=") -> #VALUE! | HP2: =AND(Datos!W22,"AAAAAGfv/98=") -> #VALUE! | HQ2: =IF(Datos!23:23,"AAAAAGfv/+A=",0) -> 0 | HR2: =AND(Datos!A23,"AAAAAGfv/+E=") -> #VALUE! | HS2: =AND(Datos!B23,"AAAAAGfv/+I=") -> #VALUE! | HT2: =AND(Datos!C23,"AAAAAGfv/+M=") -> #VALUE! | HU2: =AND(Datos!D23,"AAAAAGfv/+Q=") -> #VALUE! | HV2: =AND(Datos!E23,"AAAAAGfv/+U=") -> #VALUE! | HW2: =AND(Datos!F23,"AAAAAGfv/+Y=") -> #VALUE! | HX2: =AND(Datos!G23,"AAAAAGfv/+c=") -> #VALUE! | HY2: =AND(Datos!H23,"AAAAAGfv/+g=") -> #VALUE! | HZ2: =AND(Datos!I23,"AAAAAGfv/+k=") -> #VALUE! | IA2: =AND(Datos!J23,"AAAAAGfv/+o=") -> #VALUE! | IB2: =AND(Datos!K23,"AAAAAGfv/+s=") -> #VALUE! | IC2: =AND(Datos!L23,"AAAAAGfv/+w=") -> #VALUE! | ID2: =AND(Datos!M23,"AAAAAGfv/+0=") -> #VALUE! | IE2: =AND(Datos!N23,"AAAAAGfv/+4=") -> #VALUE! | IF2: =AND(Datos!O23,"AAAAAGfv/+8=") -> #VALUE! | IG2: =AND(Datos!P23,"AAAAAGfv//A=") -> #VALUE! | IH2: =AND(Datos!Q23,"AAAAAGfv//E=") -> #VALUE! | II2: =AND(Datos!R23,"AAAAAGfv//I=") -> #VALUE! | IJ2: =AND(Datos!S23,"AAAAAGfv//M=") -> #VALUE! | IK2: =AND(Datos!T23,"AAAAAGfv//Q=") -> #VALUE! | IL2: =AND(Datos!U23,"AAAAAGfv//U=") -> #VALUE! | IM2: =AND(Datos!V23,"AAAAAGfv//Y=") -> #VALUE! | IN2: =AND(Datos!W23,"AAAAAGfv//c=") -> #VALUE! | IO2: =IF(Datos!24:24,"AAAAAGfv//g=",0) -> 0 | IP2: =AND(Datos!A24,"AAAAAGfv//k=") -> #VALUE! | IQ2: =AND(Datos!B24,"AAAAAGfv//o=") -> #VALUE! | IR2: =AND(Datos!C24,"AAAAAGfv//s=") -> #VALUE! | IS2: =AND(Datos!D24,"AAAAAGfv//w=") -> #VALUE! | IT2: =AND(Datos!E24,"AAAAAGfv//0=") -> #VALUE! | IU2: =AND(Datos!F24,"AAAAAGfv//4=") -> #VALUE! | IV2: =AND(Datos!G24,"AAAAAGfv//8=") -> #VALUE!
A3: =AND(Datos!H24,"AAAAADa49wA=") -> #VALUE! | B3: =AND(Datos!I24,"AAAAADa49wE=") -> #VALUE! | C3: =AND(Datos!J24,"AAAAADa49wI=") -> #VALUE! | D3: =AND(Datos!K24,"AAAAADa49wM=") -> #VALUE! | E3: =AND(Datos!L24,"AAAAADa49wQ=") -> #VALUE! | F3: =AND(Datos!M24,"AAAAADa49wU=") -> #VALUE! | G3: =AND(Datos!N24,"AAAAADa49wY=") -> #VALUE! | H3: =AND(Datos!O24,"AAAAADa49wc=") -> #VALUE! | I3: =AND(Datos!P24,"AAAAADa49wg=") -> #VALUE! | J3: =AND(Datos!Q24,"AAAAADa49wk=") -> #VALUE! | K3: =AND(Datos!R24,"AAAAADa49wo=") -> #VALUE! | L3: =AND(Datos!S24,"AAAAADa49ws=") -> #VALUE! | M3: =AND(Datos!T24,"AAAAADa49ww=") -> #VALUE! | N3: =AND(Datos!U24,"AAAAADa49w0=") -> #VALUE! | O3: =AND(Datos!V24,"AAAAADa49w4=") -> #VALUE! | P3: =AND(Datos!W24,"AAAAADa49w8=") -> #VALUE! | Q3: =IF(Datos!25:25,"AAAAADa49xA=",0) -> 0 | R3: =AND(Datos!A25,"AAAAADa49xE=") -> #VALUE! | S3: =AND(Datos!B25,"AAAAADa49xI=") -> #VALUE! | T3: =AND(Datos!C25,"AAAAADa49xM=") -> #VALUE! | U3: =AND(Datos!D25,"AAAAADa49xQ=") -> #VALUE! | V3: =AND(Datos!E25,"AAAAADa49xU=") -> #VALUE! | W3: =AND(Datos!F25,"AAAAADa49xY=") -> #VALUE! | X3: =AND(Datos!G25,"AAAAADa49xc=") -> #VALUE! | Y3: =AND(Datos!H25,"AAAAADa49xg=") -> #VALUE! | Z3: =AND(Datos!I25,"AAAAADa49xk=") -> #VALUE! | AA3: =AND(Datos!J25,"AAAAADa49xo=") -> #VALUE! | AB3: =AND(Datos!K25,"AAAAADa49xs=") -> #VALUE! | AC3: =AND(Datos!L25,"AAAAADa49xw=") -> #VALUE! | AD3: =AND(Datos!M25,"AAAAADa49x0=") -> #VALUE! | AE3: =AND(Datos!N25,"AAAAADa49x4=") -> #VALUE! | AF3: =AND(Datos!O25,"AAAAADa49x8=") -> #VALUE! | AG3: =AND(Datos!P25,"AAAAADa49yA=") -> #VALUE! | AH3: =AND(Datos!Q25,"AAAAADa49yE=") -> #VALUE! | AI3: =AND(Datos!R25,"AAAAADa49yI=") -> #VALUE! | AJ3: =AND(Datos!S25,"AAAAADa49yM=") -> #VALUE! | AK3: =AND(Datos!T25,"AAAAADa49yQ=") -> #VALUE! | AL3: =AND(Datos!U25,"AAAAADa49yU=") -> #VALUE! | AM3: =AND(Datos!V25,"AAAAADa49yY=") -> #VALUE! | AN3: =AND(Datos!W25,"AAAAADa49yc=") -> #VALUE! | AO3: =IF(Datos!26:26,"AAAAADa49yg=",0) -> 0 | AP3: =AND(Datos!A26,"AAAAADa49yk=") -> #VALUE! | AQ3: =AND(Datos!B26,"AAAAADa49yo=") -> #VALUE! | AR3: =AND(Datos!C26,"AAAAADa49ys=") -> #VALUE! | AS3: =AND(Datos!D26,"AAAAADa49yw=") -> #VALUE! | AT3: =AND(Datos!E26,"AAAAADa49y0=") -> #VALUE! | AU3: =AND(Datos!F26,"AAAAADa49y4=") -> #VALUE! | AV3: =AND(Datos!G26,"AAAAADa49y8=") -> #VALUE! | AW3: =AND(Datos!H26,"AAAAADa49zA=") -> #VALUE! | AX3: =AND(Datos!I26,"AAAAADa49zE=") -> #VALUE! | AY3: =AND(Datos!J26,"AAAAADa49zI=") -> #VALUE! | AZ3: =AND(Datos!K26,"AAAAADa49zM=") -> #VALUE! | BA3: =AND(Datos!L26,"AAAAADa49zQ=") -> #VALUE! | BB3: =AND(Datos!M26,"AAAAADa49zU=") -> #VALUE! | BC3: =AND(Datos!N26,"AAAAADa49zY=") -> #VALUE! | BD3: =AND(Datos!O26,"AAAAADa49zc=") -> #VALUE! | BE3: =AND(Datos!P26,"AAAAADa49zg=") -> #VALUE! | BF3: =AND(Datos!Q26,"AAAAADa49zk=") -> #VALUE! | BG3: =AND(Datos!R26,"AAAAADa49zo=") -> #VALUE! | BH3: =AND(Datos!S26,"AAAAADa49zs=") -> #VALUE! | BI3: =AND(Datos!T26,"AAAAADa49zw=") -> #VALUE! | BJ3: =AND(Datos!U26,"AAAAADa49z0=") -> #VALUE! | BK3: =AND(Datos!V26,"AAAAADa49z4=") -> #VALUE! | BL3: =AND(Datos!W26,"AAAAADa49z8=") -> #VALUE! | BM3: =IF(Datos!27:27,"AAAAADa490A=",0) -> 0 | BN3: =AND(Datos!A27,"AAAAADa490E=") -> #VALUE! | BO3: =AND(Datos!B27,"AAAAADa490I=") -> #VALUE! | BP3: =AND(Datos!C27,"AAAAADa490M=") -> #VALUE! | BQ3: =AND(Datos!D27,"AAAAADa490Q=") -> #VALUE! | BR3: =AND(Datos!E27,"AAAAADa490U=") -> #VALUE! | BS3: =AND(Datos!#REF!,"AAAAADa490Y=") -> #REF! | BT3: =AND(Datos!F27,"AAAAADa490c=") -> #VALUE! | BU3: =AND(Datos!G27,"AAAAADa490g=") -> #VALUE! | BV3: =AND(Datos!I27,"AAAAADa490k=") -> #VALUE! | BW3: =AND(Datos!J27,"AAAAADa490o=") -> #VALUE! | BX3: =AND(Datos!K27,"AAAAADa490s=") -> #VALUE! | BY3: =AND(Datos!L27,"AAAAADa490w=") -> #VALUE! | BZ3: =AND(Datos!M27,"AAAAADa4900=") -> #VALUE! | CA3: =AND(Datos!N27,"AAAAADa4904=") -> #VALUE! | CB3: =AND(Datos!O27,"AAAAADa4908=") -> #VALUE! | CC3: =AND(Datos!P27,"AAAAADa491A=") -> #VALUE! | CD3: =AND(Datos!Q27,"AAAAADa491E=") -> #VALUE! | CE3: =AND(Datos!R27,"AAAAADa491I=") -> #VALUE! | CF3: =AND(Datos!S27,"AAAAADa491M=") -> #VALUE! | CG3: =AND(Datos!T27,"AAAAADa491Q=") -> #VALUE! | CH3: =AND(Datos!U27,"AAAAADa491U=") -> #VALUE! | CI3: =AND(Datos!V27,"AAAAADa491Y=") -> #VALUE! | CJ3: =AND(Datos!W27,"AAAAADa491c=") -> #VALUE! | CK3: =IF(Datos!28:28,"AAAAADa491g=",0) -> 0 | CL3: =AND(Datos!A28,"AAAAADa491k=") -> #VALUE! | CM3: =AND(Datos!B28,"AAAAADa491o=") -> #VALUE! | CN3: =AND(Datos!C28,"AAAAADa491s=") -> #VALUE! | CO3: =AND(Datos!D28,"AAAAADa491w=") -> #VALUE! | CP3: =AND(Datos!E28,"AAAAADa4910=") -> #VALUE! | CQ3: =AND(Datos!#REF!,"AAAAADa4914=") -> #REF! | CR3: =AND(Datos!F28,"AAAAADa4918=") -> #VALUE! | CS3: =AND(Datos!G28,"AAAAADa492A=") -> #VALUE! | CT3: =AND(Datos!I28,"AAAAADa492E=") -> #VALUE! | CU3: =AND(Datos!J28,"AAAAADa492I=") -> #VALUE! | CV3: =AND(Datos!K28,"AAAAADa492M=") -> #VALUE! | CW3: =AND(Datos!L28,"AAAAADa492Q=") -> #VALUE! | CX3: =AND(Datos!M28,"AAAAADa492U=") -> #VALUE! | CY3: =AND(Datos!N28,"AAAAADa492Y=") -> #VALUE! | CZ3: =AND(Datos!O28,"AAAAADa492c=") -> #VALUE! | DA3: =AND(Datos!P28,"AAAAADa492g=") -> #VALUE! | DB3: =AND(Datos!Q28,"AAAAADa492k=") -> #VALUE! | DC3: =AND(Datos!R28,"AAAAADa492o=") -> #VALUE! | DD3: =AND(Datos!S28,"AAAAADa492s=") -> #VALUE! | DE3: =AND(Datos!T28,"AAAAADa492w=") -> #VALUE! | DF3: =AND(Datos!U28,"AAAAADa4920=") -> #VALUE! | DG3: =AND(Datos!V28,"AAAAADa4924=") -> #VALUE! | DH3: =AND(Datos!W28,"AAAAADa4928=") -> #VALUE! | DI3: =IF(Datos!29:29,"AAAAADa493A=",0) -> 0 | DJ3: =AND(Datos!A29,"AAAAADa493E=") -> #VALUE! | DK3: =AND(Datos!B29,"AAAAADa493I=") -> #VALUE! | DL3: =AND(Datos!C29,"AAAAADa493M=") -> #VALUE! | DM3: =AND(Datos!D29,"AAAAADa493Q=") -> #VALUE! | DN3: =AND(Datos!E29,"AAAAADa493U=") -> #VALUE! | DO3: =AND(Datos!F29,"AAAAADa493Y=") -> #VALUE! | DP3: =AND(Datos!G29,"AAAAADa493c=") -> #VALUE! | DQ3: =AND(Datos!H29,"AAAAADa493g=") -> #VALUE! | DR3: =AND(Datos!I29,"AAAAADa493k=") -> #VALUE! | DS3: =AND(Datos!J29,"AAAAADa493o=") -> #VALUE! | DT3: =AND(Datos!K29,"AAAAADa493s=") -> #VALUE! | DU3: =AND(Datos!L29,"AAAAADa493w=") -> #VALUE! | DV3: =AND(Datos!M29,"AAAAADa4930=") -> #VALUE! | DW3: =AND(Datos!N29,"AAAAADa4934=") -> #VALUE! | DX3: =AND(Datos!O29,"AAAAADa4938=") -> #VALUE! | DY3: =AND(Datos!P29,"AAAAADa494A=") -> #VALUE! | DZ3: =AND(Datos!Q29,"AAAAADa494E=") -> #VALUE! | EA3: =AND(Datos!R29,"AAAAADa494I=") -> #VALUE! | EB3: =AND(Datos!S29,"AAAAADa494M=") -> #VALUE! | EC3: =AND(Datos!T29,"AAAAADa494Q=") -> #VALUE! | ED3: =AND(Datos!U29,"AAAAADa494U=") -> #VALUE! | EE3: =AND(Datos!V29,"AAAAADa494Y=") -> #VALUE! | EF3: =AND(Datos!W29,"AAAAADa494c=") -> #VALUE! | EG3: =IF(Datos!31:31,"AAAAADa494g=",0) -> 0 | EH3: =AND(Datos!A31,"AAAAADa494k=") -> #VALUE! | EI3: =AND(Datos!B31,"AAAAADa494o=") -> #VALUE! | EJ3: =AND(Datos!C31,"AAAAADa494s=") -> #VALUE! | EK3: =AND(Datos!D31,"AAAAADa494w=") -> #VALUE! | EL3: =AND(Datos!E31,"AAAAADa4940=") -> #VALUE! | EM3: =AND(Datos!F31,"AAAAADa4944=") -> #VALUE! | EN3: =AND(Datos!G31,"AAAAADa4948=") -> #VALUE! | EO3: =AND(Datos!H31,"AAAAADa495A=") -> #VALUE! | EP3: =AND(Datos!I31,"AAAAADa495E=") -> #VALUE! | EQ3: =AND(Datos!J31,"AAAAADa495I=") -> #VALUE! | ER3: =AND(Datos!K31,"AAAAADa495M=") -> #VALUE! | ES3: =AND(Datos!L31,"AAAAADa495Q=") -> #VALUE! | ET3: =AND(Datos!M31,"AAAAADa495U=") -> #VALUE! | EU3: =AND(Datos!N31,"AAAAADa495Y=") -> #VALUE! | EV3: =AND(Datos!O31,"AAAAADa495c=") -> #VALUE! | EW3: =AND(Datos!P31,"AAAAADa495g=") -> #VALUE! | EX3: =AND(Datos!Q31,"AAAAADa495k=") -> #VALUE! | EY3: =AND(Datos!R31,"AAAAADa495o=") -> #VALUE! | EZ3: =AND(Datos!S31,"AAAAADa495s=") -> #VALUE! | FA3: =AND(Datos!T31,"AAAAADa495w=") -> #VALUE! | FB3: =AND(Datos!U31,"AAAAADa4950=") -> #VALUE! | FC3: =AND(Datos!V31,"AAAAADa4954=") -> #VALUE! | FD3: =AND(Datos!W31,"AAAAADa4958=") -> #VALUE! | FE3: =IF(Datos!32:32,"AAAAADa496A=",0) -> 0 | FF3: =AND(Datos!A32,"AAAAADa496E=") -> #VALUE! | FG3: =AND(Datos!B32,"AAAAADa496I=") -> #VALUE! | FH3: =AND(Datos!C32,"AAAAADa496M=") -> #VALUE! | FI3: =AND(Datos!D32,"AAAAADa496Q=") -> #VALUE! | FJ3: =AND(Datos!E32,"AAAAADa496U=") -> #VALUE! | FK3: =AND(Datos!F32,"AAAAADa496Y=") -> #VALUE! | FL3: =AND(Datos!G32,"AAAAADa496c=") -> #VALUE! | FM3: =AND(Datos!H32,"AAAAADa496g=") -> #VALUE! | FN3: =AND(Datos!I32,"AAAAADa496k=") -> #VALUE! | FO3: =AND(Datos!J32,"AAAAADa496o=") -> #VALUE! | FP3: =AND(Datos!K32,"AAAAADa496s=") -> #VALUE! | FQ3: =AND(Datos!L32,"AAAAADa496w=") -> #VALUE! | FR3: =AND(Datos!M32,"AAAAADa4960=") -> #VALUE! | FS3: =AND(Datos!N32,"AAAAADa4964=") -> #VALUE! | FT3: =AND(Datos!O32,"AAAAADa4968=") -> #VALUE! | FU3: =AND(Datos!P32,"AAAAADa497A=") -> #VALUE! | FV3: =AND(Datos!Q32,"AAAAADa497E=") -> #VALUE! | FW3: =AND(Datos!R32,"AAAAADa497I=") -> #VALUE! | FX3: =AND(Datos!S32,"AAAAADa497M=") -> #VALUE! | FY3: =AND(Datos!T32,"AAAAADa497Q=") -> #VALUE! | FZ3: =AND(Datos!U32,"AAAAADa497U=") -> #VALUE! | GA3: =AND(Datos!V32,"AAAAADa497Y=") -> #VALUE! | GB3: =AND(Datos!W32,"AAAAADa497c=") -> #VALUE! | GC3: =IF(Datos!33:33,"AAAAADa497g=",0) -> 0 | GD3: =AND(Datos!A33,"AAAAADa497k=") -> #VALUE! | GE3: =AND(Datos!B33,"AAAAADa497o=") -> #VALUE! | GF3: =AND(Datos!C33,"AAAAADa497s=") -> #VALUE! | GG3: =AND(Datos!D33,"AAAAADa497w=") -> #VALUE! | GH3: =AND(Datos!E33,"AAAAADa4970=") -> #VALUE! | GI3: =AND(Datos!F33,"AAAAADa4974=") -> #VALUE! | GJ3: =AND(Datos!G33,"AAAAADa4978=") -> #VALUE! | GK3: =AND(Datos!H33,"AAAAADa498A=") -> #VALUE! | GL3: =AND(Datos!I33,"AAAAADa498E=") -> #VALUE! | GM3: =AND(Datos!J33,"AAAAADa498I=") -> #VALUE! | GN3: =AND(Datos!K33,"AAAAADa498M=") -> #VALUE! | GO3: =AND(Datos!L33,"AAAAADa498Q=") -> #VALUE! | GP3: =AND(Datos!M33,"AAAAADa498U=") -> #VALUE! | GQ3: =AND(Datos!N33,"AAAAADa498Y=") -> #VALUE! | GR3: =AND(Datos!O33,"AAAAADa498c=") -> #VALUE! | GS3: =AND(Datos!P33,"AAAAADa498g=") -> #VALUE! | GT3: =AND(Datos!Q33,"AAAAADa498k=") -> #VALUE! | GU3: =AND(Datos!R33,"AAAAADa498o=") -> #VALUE! | GV3: =AND(Datos!S33,"AAAAADa498s=") -> #VALUE! | GW3: =AND(Datos!T33,"AAAAADa498w=") -> #VALUE! | GX3: =AND(Datos!U33,"AAAAADa4980=") -> #VALUE! | GY3: =AND(Datos!V33,"AAAAADa4984=") -> #VALUE! | GZ3: =AND(Datos!W33,"AAAAADa4988=") -> #VALUE! | HA3: =IF(Datos!34:34,"AAAAADa499A=",0) -> 0 | HB3: =AND(Datos!A34,"AAAAADa499E=") -> #VALUE! | HC3: =AND(Datos!B34,"AAAAADa499I=") -> #VALUE! | HD3: =AND(Datos!C34,"AAAAADa499M=") -> #VALUE! | HE3: =AND(Datos!D34,"AAAAADa499Q=") -> #VALUE! | HF3: =AND(Datos!E34,"AAAAADa499U=") -> #VALUE! | HG3: =AND(Datos!F34,"AAAAADa499Y=") -> #VALUE! | HH3: =AND(Datos!G34,"AAAAADa499c=") -> #VALUE! | HI3: =AND(Datos!H34,"AAAAADa499g=") -> #VALUE! | HJ3: =AND(Datos!I34,"AAAAADa499k=") -> #VALUE! | HK3: =AND(Datos!J34,"AAAAADa499o=") -> #VALUE! | HL3: =AND(Datos!K34,"AAAAADa499s=") -> #VALUE! | HM3: =AND(Datos!L34,"AAAAADa499w=") -> #VALUE! | HN3: =AND(Datos!M34,"AAAAADa4990=") -> #VALUE! | HO3: =AND(Datos!N34,"AAAAADa4994=") -> #VALUE! | HP3: =AND(Datos!O34,"AAAAADa4998=") -> #VALUE! | HQ3: =AND(Datos!P34,"AAAAADa49+A=") -> #VALUE! | HR3: =AND(Datos!Q34,"AAAAADa49+E=") -> #VALUE! | HS3: =AND(Datos!R34,"AAAAADa49+I=") -> #VALUE! | HT3: =AND(Datos!S34,"AAAAADa49+M=") -> #VALUE! | HU3: =AND(Datos!T34,"AAAAADa49+Q=") -> #VALUE! | HV3: =AND(Datos!U34,"AAAAADa49+U=") -> #VALUE! | HW3: =AND(Datos!V34,"AAAAADa49+Y=") -> #VALUE! | HX3: =AND(Datos!W34,"AAAAADa49+c=") -> #VALUE! | HY3: =IF(Datos!35:35,"AAAAADa49+g=",0) -> 0 | HZ3: =AND(Datos!A35,"AAAAADa49+k=") -> #VALUE! | IA3: =AND(Datos!B35,"AAAAADa49+o=") -> #VALUE! | IB3: =AND(Datos!C35,"AAAAADa49+s=") -> #VALUE! | IC3: =AND(Datos!D35,"AAAAADa49+w=") -> #VALUE! | ID3: =AND(Datos!E35,"AAAAADa49+0=") -> #VALUE! | IE3: =AND(Datos!F35,"AAAAADa49+4=") -> #VALUE! | IF3: =AND(Datos!G35,"AAAAADa49+8=") -> #VALUE! | IG3: =AND(Datos!H35,"AAAAADa49/A=") -> #VALUE! | IH3: =AND(Datos!I35,"AAAAADa49/E=") -> #VALUE! | II3: =AND(Datos!J35,"AAAAADa49/I=") -> #VALUE! | IJ3: =AND(Datos!K35,"AAAAADa49/M=") -> #VALUE! | IK3: =AND(Datos!L35,"AAAAADa49/Q=") -> #VALUE! | IL3: =AND(Datos!M35,"AAAAADa49/U=") -> #VALUE! | IM3: =AND(Datos!N35,"AAAAADa49/Y=") -> #VALUE! | IN3: =AND(Datos!O35,"AAAAADa49/c=") -> #VALUE! | IO3: =AND(Datos!P35,"AAAAADa49/g=") -> #VALUE! | IP3: =AND(Datos!Q35,"AAAAADa49/k=") -> #VALUE! | IQ3: =AND(Datos!R35,"AAAAADa49/o=") -> #VALUE! | IR3: =AND(Datos!S35,"AAAAADa49/s=") -> #VALUE! | IS3: =AND(Datos!T35,"AAAAADa49/w=") -> #VALUE! | IT3: =AND(Datos!U35,"AAAAADa49/0=") -> #VALUE! | IU3: =AND(Datos!V35,"AAAAADa49/4=") -> #VALUE! | IV3: =AND(Datos!W35,"AAAAADa49/8=") -> #VALUE!
A4: =IF(Datos!36:36,"AAAAAH/0uwA=",0) -> 0 | B4: =AND(Datos!A36,"AAAAAH/0uwE=") -> #VALUE! | C4: =AND(Datos!B36,"AAAAAH/0uwI=") -> #VALUE! | D4: =AND(Datos!G36,"AAAAAH/0uwM=") -> #VALUE! | E4: =AND(Datos!H36,"AAAAAH/0uwQ=") -> #VALUE! | F4: =AND(Datos!I36,"AAAAAH/0uwU=") -> #VALUE! | G4: =AND(Datos!J36,"AAAAAH/0uwY=") -> #VALUE! | H4: =AND(Datos!#REF!,"AAAAAH/0uwc=") -> #REF! | I4: =AND(Datos!K36,"AAAAAH/0uwg=") -> #VALUE! | J4: =AND(Datos!L36,"AAAAAH/0uwk=") -> #VALUE! | K4: =AND(Datos!#REF!,"AAAAAH/0uwo=") -> #REF! | L4: =AND(Datos!#REF!,"AAAAAH/0uws=") -> #REF! | M4: =AND(Datos!#REF!,"AAAAAH/0uww=") -> #REF! | N4: =AND(Datos!#REF!,"AAAAAH/0uw0=") -> #REF! | O4: =AND(Datos!N36,"AAAAAH/0uw4=") -> #VALUE! | P4: =AND(Datos!O36,"AAAAAH/0uw8=") -> #VALUE! | Q4: =AND(Datos!P36,"AAAAAH/0uxA=") -> #VALUE! | R4: =AND(Datos!Q36,"AAAAAH/0uxE=") -> #VALUE! | S4: =AND(Datos!R36,"AAAAAH/0uxI=") -> #VALUE! | T4: =AND(Datos!S36,"AAAAAH/0uxM=") -> #VALUE! | U4: =AND(Datos!T36,"AAAAAH/0uxQ=") -> #VALUE! | V4: =AND(Datos!U36,"AAAAAH/0uxU=") -> #VALUE! | W4: =AND(Datos!V36,"AAAAAH/0uxY=") -> #VALUE! | X4: =AND(Datos!W36,"AAAAAH/0uxc=") -> #VALUE! | Y4: =IF(Datos!37:37,"AAAAAH/0uxg=",0) -> 0 | Z4: =AND(Datos!A37,"AAAAAH/0uxk=") -> #VALUE! | AA4: =AND(Datos!B37,"AAAAAH/0uxo=") -> #VALUE! | AB4: =AND(Datos!G37,"AAAAAH/0uxs=") -> #VALUE! | AC4: =AND(Datos!H37,"AAAAAH/0uxw=") -> #VALUE! | AD4: =AND(Datos!I37,"AAAAAH/0ux0=") -> #VALUE! | AE4: =AND(Datos!J37,"AAAAAH/0ux4=") -> #VALUE! | AF4: =AND(Datos!#REF!,"AAAAAH/0ux8=") -> #REF! | AG4: =AND(Datos!K37,"AAAAAH/0uyA=") -> #VALUE! | AH4: =AND(Datos!L37,"AAAAAH/0uyE=") -> #VALUE! | AI4: =AND(Datos!#REF!,"AAAAAH/0uyI=") -> #REF! | AJ4: =AND(Datos!#REF!,"AAAAAH/0uyM=") -> #REF! | AK4: =AND(Datos!#REF!,"AAAAAH/0uyQ=") -> #REF! | AL4: =AND(Datos!#REF!,"AAAAAH/0uyU=") -> #REF! | AM4: =AND(Datos!N37,"AAAAAH/0uyY=") -> #VALUE! | AN4: =AND(Datos!O37,"AAAAAH/0uyc=") -> #VALUE! | AO4: =AND(Datos!P37,"AAAAAH/0uyg=") -> #VALUE! | AP4: =AND(Datos!Q37,"AAAAAH/0uyk=") -> #VALUE! | AQ4: =AND(Datos!R37,"AAAAAH/0uyo=") -> #VALUE! | AR4: =AND(Datos!S37,"AAAAAH/0uys=") -> #VALUE! | AS4: =AND(Datos!T37,"AAAAAH/0uyw=") -> #VALUE! | AT4: =AND(Datos!U37,"AAAAAH/0uy0=") -> #VALUE! | AU4: =AND(Datos!V37,"AAAAAH/0uy4=") -> #VALUE! | AV4: =AND(Datos!W37,"AAAAAH/0uy8=") -> #VALUE! | AW4: =IF(Datos!38:38,"AAAAAH/0uzA=",0) -> 0 | AX4: =AND(Datos!A38,"AAAAAH/0uzE=") -> #VALUE! | AY4: =AND(Datos!B38,"AAAAAH/0uzI=") -> #VALUE! | AZ4: =AND(Datos!G38,"AAAAAH/0uzM=") -> #VALUE! | BA4: =AND(Datos!H38,"AAAAAH/0uzQ=") -> #VALUE! | BB4: =AND(Datos!I38,"AAAAAH/0uzU=") -> #VALUE! | BC4: =AND(Datos!J38,"AAAAAH/0uzY=") -> #VALUE! | BD4: =AND(Datos!#REF!,"AAAAAH/0uzc=") -> #REF! | BE4: =AND(Datos!K38,"AAAAAH/0uzg=") -> #VALUE! | BF4: =AND(Datos!L38,"AAAAAH/0uzk=") -> #VALUE! | BG4: =AND(Datos!#REF!,"AAAAAH/0uzo=") -> #REF! | BH4: =AND(Datos!#REF!,"AAAAAH/0uzs=") -> #REF! | BI4: =AND(Datos!#REF!,"AAAAAH/0uzw=") -> #REF! | BJ4: =AND(Datos!#REF!,"AAAAAH/0uz0=") -> #REF! | BK4: =AND(Datos!N38,"AAAAAH/0uz4=") -> #VALUE! | BL4: =AND(Datos!O38,"AAAAAH/0uz8=") -> #VALUE! | BM4: =AND(Datos!P38,"AAAAAH/0u0A=") -> #VALUE! | BN4: =AND(Datos!Q38,"AAAAAH/0u0E=") -> #VALUE! | BO4: =AND(Datos!R38,"AAAAAH/0u0I=") -> #VALUE! | BP4: =AND(Datos!S38,"AAAAAH/0u0M=") -> #VALUE! | BQ4: =AND(Datos!T38,"AAAAAH/0u0Q=") -> #VALUE! | BR4: =AND(Datos!U38,"AAAAAH/0u0U=") -> #VALUE! | BS4: =AND(Datos!V38,"AAAAAH/0u0Y=") -> #VALUE! | BT4: =AND(Datos!W38,"AAAAAH/0u0c=") -> #VALUE! | BU4: =IF(Datos!39:39,"AAAAAH/0u0g=",0) -> 0 | BV4: =AND(Datos!A39,"AAAAAH/0u0k=") -> #VALUE! | BW4: =AND(Datos!B39,"AAAAAH/0u0o=") -> #VALUE! | BX4: =AND(Datos!G39,"AAAAAH/0u0s=") -> #VALUE! | BY4: =AND(Datos!H39,"AAAAAH/0u0w=") -> #VALUE! | BZ4: =AND(Datos!I39,"AAAAAH/0u00=") -> #VALUE! | CA4: =AND(Datos!J39,"AAAAAH/0u04=") -> #VALUE! | CB4: =AND(Datos!#REF!,"AAAAAH/0u08=") -> #REF! | CC4: =AND(Datos!K39,"AAAAAH/0u1A=") -> #VALUE! | CD4: =AND(Datos!L39,"AAAAAH/0u1E=") -> #VALUE! | CE4: =AND(Datos!#REF!,"AAAAAH/0u1I=") -> #REF! | CF4: =AND(Datos!#REF!,"AAAAAH/0u1M=") -> #REF! | CG4: =AND(Datos!#REF!,"AAAAAH/0u1Q=") -> #REF! | CH4: =AND(Datos!#REF!,"AAAAAH/0u1U=") -> #REF! | CI4: =AND(Datos!N39,"AAAAAH/0u1Y=") -> #VALUE! | CJ4: =AND(Datos!O39,"AAAAAH/0u1c=") -> #VALUE! | CK4: =AND(Datos!P39,"AAAAAH/0u1g=") -> #VALUE! | CL4: =AND(Datos!Q39,"AAAAAH/0u1k=") -> #VALUE! | CM4: =AND(Datos!R39,"AAAAAH/0u1o=") -> #VALUE! | CN4: =AND(Datos!S39,"AAAAAH/0u1s=") -> #VALUE! | CO4: =AND(Datos!T39,"AAAAAH/0u1w=") -> #VALUE! | CP4: =AND(Datos!U39,"AAAAAH/0u10=") -> #VALUE! | CQ4: =AND(Datos!V39,"AAAAAH/0u14=") -> #VALUE! | CR4: =AND(Datos!W39,"AAAAAH/0u18=") -> #VALUE! | CS4: =IF(Datos!40:40,"AAAAAH/0u2A=",0) -> 0 | CT4: =AND(Datos!A40,"AAAAAH/0u2E=") -> #VALUE! | CU4: =AND(Datos!B40,"AAAAAH/0u2I=") -> #VALUE! | CV4: =AND(Datos!G40,"AAAAAH/0u2M=") -> #VALUE! | CW4: =AND(Datos!H40,"AAAAAH/0u2Q=") -> #VALUE! | CX4: =AND(Datos!I40,"AAAAAH/0u2U=") -> #VALUE! | CY4: =AND(Datos!J40,"AAAAAH/0u2Y=") -> #VALUE! | CZ4: =AND(Datos!#REF!,"AAAAAH/0u2c=") -> #REF! | DA4: =AND(Datos!K40,"AAAAAH/0u2g=") -> #VALUE! | DB4: =AND(Datos!L40,"AAAAAH/0u2k=") -> #VALUE! | DC4: =AND(Datos!#REF!,"AAAAAH/0u2o=") -> #REF! | DD4: =AND(Datos!#REF!,"AAAAAH/0u2s=") -> #REF! | DE4: =AND(Datos!#REF!,"AAAAAH/0u2w=") -> #REF! | DF4: =AND(Datos!#REF!,"AAAAAH/0u20=") -> #REF! | DG4: =AND(Datos!N40,"AAAAAH/0u24=") -> #VALUE! | DH4: =AND(Datos!O40,"AAAAAH/0u28=") -> #VALUE! | DI4: =AND(Datos!P40,"AAAAAH/0u3A=") -> #VALUE! | DJ4: =AND(Datos!Q40,"AAAAAH/0u3E=") -> #VALUE! | DK4: =AND(Datos!R40,"AAAAAH/0u3I=") -> #VALUE! | DL4: =AND(Datos!S40,"AAAAAH/0u3M=") -> #VALUE! | DM4: =AND(Datos!T40,"AAAAAH/0u3Q=") -> #VALUE! | DN4: =AND(Datos!U40,"AAAAAH/0u3U=") -> #VALUE! | DO4: =AND(Datos!V40,"AAAAAH/0u3Y=") -> #VALUE! | DP4: =AND(Datos!W40,"AAAAAH/0u3c=") -> #VALUE! | DQ4: =IF(Datos!42:42,"AAAAAH/0u3g=",0) -> 0 | DR4: =AND(Datos!A42,"AAAAAH/0u3k=") -> #VALUE! | DS4: =AND(Datos!B42,"AAAAAH/0u3o=") -> #VALUE! | DT4: =AND(Datos!C42,"AAAAAH/0u3s=") -> #VALUE! | DU4: =AND(Datos!D42,"AAAAAH/0u3w=") -> #VALUE! | DV4: =AND(Datos!E42,"AAAAAH/0u30=") -> #VALUE! | DW4: =AND(Datos!F42,"AAAAAH/0u34=") -> #VALUE! | DX4: =AND(Datos!G42,"AAAAAH/0u38=") -> #VALUE! | DY4: =AND(Datos!H42,"AAAAAH/0u4A=") -> #VALUE! | DZ4: =AND(Datos!I42,"AAAAAH/0u4E=") -> #VALUE! | EA4: =AND(Datos!J42,"AAAAAH/0u4I=") -> #VALUE! | EB4: =AND(Datos!K42,"AAAAAH/0u4M=") -> #VALUE! | EC4: =AND(Datos!L42,"AAAAAH/0u4Q=") -> #VALUE! | ED4: =AND(Datos!M42,"AAAAAH/0u4U=") -> #VALUE! | EE4: =AND(Datos!N42,"AAAAAH/0u4Y=") -> #VALUE! | EF4: =AND(Datos!O42,"AAAAAH/0u4c=") -> #VALUE! | EG4: =AND(Datos!P42,"AAAAAH/0u4g=") -> #VALUE! | EH4: =AND(Datos!Q42,"AAAAAH/0u4k=") -> #VALUE! | EI4: =AND(Datos!R42,"AAAAAH/0u4o=") -> #VALUE! | EJ4: =AND(Datos!S42,"AAAAAH/0u4s=") -> #VALUE! | EK4: =AND(Datos!T42,"AAAAAH/0u4w=") -> #VALUE! | EL4: =AND(Datos!U42,"AAAAAH/0u40=") -> #VALUE! | EM4: =AND(Datos!V42,"AAAAAH/0u44=") -> #VALUE! | EN4: =AND(Datos!W42,"AAAAAH/0u48=") -> #VALUE! | EO4: =IF(Datos!43:43,"AAAAAH/0u5A=",0) -> 0 | EP4: =AND(Datos!A43,"AAAAAH/0u5E=") -> #VALUE! | EQ4: =AND(Datos!B43,"AAAAAH/0u5I=") -> #VALUE! | ER4: =AND(Datos!C43,"AAAAAH/0u5M=") -> #VALUE! | ES4: =AND(Datos!D43,"AAAAAH/0u5Q=") -> #VALUE! | ET4: =AND(Datos!E43,"AAAAAH/0u5U=") -> #VALUE! | EU4: =AND(Datos!F43,"AAAAAH/0u5Y=") -> #VALUE! | EV4: =AND(Datos!G43,"AAAAAH/0u5c=") -> #VALUE! | EW4: =AND(Datos!H43,"AAAAAH/0u5g=") -> #VALUE! | EX4: =AND(Datos!I43,"AAAAAH/0u5k=") -> #VALUE! | EY4: =AND(Datos!J43,"AAAAAH/0u5o=") -> #VALUE! | EZ4: =AND(Datos!K43,"AAAAAH/0u5s=") -> #VALUE! | FA4: =AND(Datos!L43,"AAAAAH/0u5w=") -> #VALUE! | FB4: =AND(Datos!M43,"AAAAAH/0u50=") -> #VALUE! | FC4: =AND(Datos!N43,"AAAAAH/0u54=") -> #VALUE! | FD4: =AND(Datos!O43,"AAAAAH/0u58=") -> #VALUE! | FE4: =AND(Datos!P43,"AAAAAH/0u6A=") -> #VALUE! | FF4: =AND(Datos!Q43,"AAAAAH/0u6E=") -> #VALUE! | FG4: =AND(Datos!R43,"AAAAAH/0u6I=") -> #VALUE! | FH4: =AND(Datos!S43,"AAAAAH/0u6M=") -> #VALUE! | FI4: =AND(Datos!T43,"AAAAAH/0u6Q=") -> #VALUE! | FJ4: =AND(Datos!U43,"AAAAAH/0u6U=") -> #VALUE! | FK4: =AND(Datos!V43,"AAAAAH/0u6Y=") -> #VALUE! | FL4: =AND(Datos!W43,"AAAAAH/0u6c=") -> #VALUE! | FM4: =IF(Datos!44:44,"AAAAAH/0u6g=",0) -> 0 | FN4: =AND(Datos!A44,"AAAAAH/0u6k=") -> #VALUE! | FO4: =AND(Datos!B44,"AAAAAH/0u6o=") -> #VALUE! | FP4: =AND(Datos!C44,"AAAAAH/0u6s=") -> #VALUE! | FQ4: =AND(Datos!D44,"AAAAAH/0u6w=") -> #VALUE! | FR4: =AND(Datos!E44,"AAAAAH/0u60=") -> #VALUE! | FS4: =AND(Datos!F44,"AAAAAH/0u64=") -> #VALUE! | FT4: =AND(Datos!G44,"AAAAAH/0u68=") -> #VALUE! | FU4: =AND(Datos!H44,"AAAAAH/0u7A=") -> #VALUE! | FV4: =AND(Datos!I44,"AAAAAH/0u7E=") -> #VALUE! | FW4: =AND(Datos!J44,"AAAAAH/0u7I=") -> #VALUE! | FX4: =AND(Datos!K44,"AAAAAH/0u7M=") -> #VALUE! | FY4: =AND(Datos!L44,"AAAAAH/0u7Q=") -> #VALUE! | FZ4: =AND(Datos!M44,"AAAAAH/0u7U=") -> #VALUE! | GA4: =AND(Datos!N44,"AAAAAH/0u7Y=") -> #VALUE! | GB4: =AND(Datos!O44,"AAAAAH/0u7c=") -> #VALUE! | GC4: =AND(Datos!P44,"AAAAAH/0u7g=") -> #VALUE! | GD4: =AND(Datos!Q44,"AAAAAH/0u7k=") -> #VALUE! | GE4: =AND(Datos!R44,"AAAAAH/0u7o=") -> #VALUE! | GF4: =AND(Datos!S44,"AAAAAH/0u7s=") -> #VALUE! | GG4: =AND(Datos!T44,"AAAAAH/0u7w=") -> #VALUE! | GH4: =AND(Datos!U44,"AAAAAH/0u70=") -> #VALUE! | GI4: =AND(Datos!V44,"AAAAAH/0u74=") -> #VALUE! | GJ4: =AND(Datos!W44,"AAAAAH/0u78=") -> #VALUE! | GK4: =IF(Datos!45:45,"AAAAAH/0u8A=",0) -> 0 | GL4: =AND(Datos!A45,"AAAAAH/0u8E=") -> #VALUE! | GM4: =AND(Datos!B45,"AAAAAH/0u8I=") -> #VALUE! | GN4: =AND(Datos!C45,"AAAAAH/0u8M=") -> #VALUE! | GO4: =AND(Datos!D45,"AAAAAH/0u8Q=") -> #VALUE! | GP4: =AND(Datos!E45,"AAAAAH/0u8U=") -> #VALUE! | GQ4: =AND(Datos!F45,"AAAAAH/0u8Y=") -> #VALUE! | GR4: =AND(Datos!G45,"AAAAAH/0u8c=") -> #VALUE! | GS4: =AND(Datos!H45,"AAAAAH/0u8g=") -> #VALUE! | GT4: =AND(Datos!I45,"AAAAAH/0u8k=") -> #VALUE! | GU4: =AND(Datos!J45,"AAAAAH/0u8o=") -> #VALUE! | GV4: =AND(Datos!K45,"AAAAAH/0u8s=") -> #VALUE! | GW4: =AND(Datos!L45,"AAAAAH/0u8w=") -> #VALUE! | GX4: =AND(Datos!M45,"AAAAAH/0u80=") -> #VALUE! | GY4: =AND(Datos!N45,"AAAAAH/0u84=") -> #VALUE! | GZ4: =AND(Datos!O45,"AAAAAH/0u88=") -> #VALUE! | HA4: =AND(Datos!P45,"AAAAAH/0u9A=") -> #VALUE! | HB4: =AND(Datos!Q45,"AAAAAH/0u9E=") -> #VALUE! | HC4: =AND(Datos!R45,"AAAAAH/0u9I=") -> #VALUE! | HD4: =AND(Datos!S45,"AAAAAH/0u9M=") -> #VALUE! | HE4: =AND(Datos!T45,"AAAAAH/0u9Q=") -> #VALUE! | HF4: =AND(Datos!U45,"AAAAAH/0u9U=") -> #VALUE! | HG4: =AND(Datos!V45,"AAAAAH/0u9Y=") -> #VALUE! | HH4: =AND(Datos!W45,"AAAAAH/0u9c=") -> #VALUE! | HI4: =IF(Datos!46:46,"AAAAAH/0u9g=",0) -> 0 | HJ4: =AND(Datos!A46,"AAAAAH/0u9k=") -> #VALUE! | HK4: =AND(Datos!B46,"AAAAAH/0u9o=") -> #VALUE! | HL4: =AND(Datos!G46,"AAAAAH/0u9s=") -> #VALUE! | HM4: =AND(Datos!H46,"AAAAAH/0u9w=") -> #VALUE! | HN4: =AND(Datos!I46,"AAAAAH/0u90=") -> #VALUE! | HO4: =AND(Datos!J46,"AAAAAH/0u94=") -> #VALUE! | HP4: =AND(Datos!#REF!,"AAAAAH/0u98=") -> #REF! | HQ4: =AND(Datos!K46,"AAAAAH/0u+A=") -> #VALUE! | HR4: =AND(Datos!L46,"AAAAAH/0u+E=") -> #VALUE! | HS4: =AND(Datos!#REF!,"AAAAAH/0u+I=") -> #REF! | HT4: =AND(Datos!#REF!,"AAAAAH/0u+M=") -> #REF! | HU4: =AND(Datos!#REF!,"AAAAAH/0u+Q=") -> #REF! | HV4: =AND(Datos!M46,"AAAAAH/0u+U=") -> #VALUE! | HW4: =AND(Datos!N46,"AAAAAH/0u+Y=") -> #VALUE! | HX4: =AND(Datos!O46,"AAAAAH/0u+c=") -> #VALUE! | HY4: =AND(Datos!P46,"AAAAAH/0u+g=") -> #VALUE! | HZ4: =AND(Datos!Q46,"AAAAAH/0u+k=") -> #VALUE! | IA4: =AND(Datos!R46,"AAAAAH/0u+o=") -> #VALUE! | IB4: =AND(Datos!S46,"AAAAAH/0u+s=") -> #VALUE! | IC4: =AND(Datos!T46,"AAAAAH/0u+w=") -> #VALUE! | ID4: =AND(Datos!U46,"AAAAAH/0u+0=") -> #VALUE! | IE4: =AND(Datos!V46,"AAAAAH/0u+4=") -> #VALUE! | IF4: =AND(Datos!W46,"AAAAAH/0u+8=") -> #VALUE! | IG4: =IF(Datos!47:47,"AAAAAH/0u/A=",0) -> 0 | IH4: =AND(Datos!A47,"AAAAAH/0u/E=") -> #VALUE! | II4: =AND(Datos!B47,"AAAAAH/0u/I=") -> #VALUE! | IJ4: =AND(Datos!G47,"AAAAAH/0u/M=") -> #VALUE! | IK4: =AND(Datos!H47,"AAAAAH/0u/Q=") -> #VALUE! | IL4: =AND(Datos!I47,"AAAAAH/0u/U=") -> #VALUE! | IM4: =AND(Datos!J47,"AAAAAH/0u/Y=") -> #VALUE! | IN4: =AND(Datos!#REF!,"AAAAAH/0u/c=") -> #REF! | IO4: =AND(Datos!K47,"AAAAAH/0u/g=") -> #VALUE! | IP4: =AND(Datos!L47,"AAAAAH/0u/k=") -> #VALUE! | IQ4: =AND(Datos!#REF!,"AAAAAH/0u/o=") -> #REF! | IR4: =AND(Datos!#REF!,"AAAAAH/0u/s=") -> #REF! | IS4: =AND(Datos!#REF!,"AAAAAH/0u/w=") -> #REF! | IT4: =AND(Datos!M47,"AAAAAH/0u/0=") -> #VALUE! | IU4: =AND(Datos!N47,"AAAAAH/0u/4=") -> #VALUE! | IV4: =AND(Datos!O47,"AAAAAH/0u/8=") -> #VALUE!
